Workbook

Sheet read_me
A3: ctry | B3: sheet name | C3: description | D3: source | E3: time span | F3: note
A4: UK | B4: rgdp | C4: Gross Domestic Product: chained volume measures: Seasonally adjusted £m | D4: ONS | E4: 1970Q1-2025Q2 | F4: https://www.ons.gov.uk/economy/grossdomesticproductgdp/timeseries/abmi/pn2
A5: UK | B5: g4rdgp | C5: delta4 ln rgdp * 100 | D5: own computations | E5: 1971Q1-2025Q2
A6: UK | B6: qoq_rgdp | C6: delta ln of rgdp * 100 | D6: own computations | E6: 1970Q2-2025Q2
A7: UK | B7: g4Infl | C7: Inflation | D7: IMF | E7: 1970Q1-2025Q2 | F7: https://data.imf.org/en/Data-Explorer?datasetUrn=IMF.STA:CPI(4.0.0) (uk - cpi - all items - period avg (yoy) - quarterly - all
A8: UK | B8: infl | C8: CPIH ANNUAL RATE 00: ALL ITEMS 2015=100 | D8: ONS | E8: 1989Q1-2025Q2 | F8: https://www.ons.gov.uk/economy/inflationandpriceindices/timeseries/l55o/mm23
A9: UK | B9: credit_to_gdp_bank | C9: United Kingdom - Credit from Banks, domestic to Private non-financial sector at Market value, Percentage of GDP, Adjusted for breaks | D9: BIS | E9: 1970Q1-2025Q1 | F9: https://data.bis.org/topics/TOTAL_CREDIT/BIS,WS_TC,2.0/Q.GB.P.B.M.770.A
A10: UK | B10: credit_to_gdp_all | C10: United Kingdom - Credit from All sectors to Private non-financial sector at Market value, Percentage of GDP, Adjusted for breaks | D10: BIS | E10: 1970Q1-2025Q1 | F10: https://data.bis.org/topics/TOTAL_CREDIT/BIS,WS_TC,2.0/Q.GB.P.A.M.770.A
A11: UK | B11: delta_3y_credit_to_gdp_all | C11: delta 3y - United Kingdom - Credit from All sectors to Private non-financial sector at Market value, Percentage of GDP, Adjusted for breaks | D11: own computations | E11: 1973Q1-2025Q1
A12: ALL | B12: vix | C12: CBOE Volatility Index: VIX - US | D12: FRED | E12: 1970Q3-2025Q3 | F12: https://fred.stlouisfed.org/series/VIXCLS# || the series is spliced with S&P mrkt vol pre 1990q1
A13: UK | B13: bond_spread | C13: Corporate bond spread | D13: a-millennium-of-macroeconomic-data-for-the-uk + own computations + countercyclical capital buffer.xslsx (BOE) | E13: 1970Q1-2025Q3 | F13: we aggregate at the quarterly level (avg for the months in the quarter) the monthly series construcuted for inflation at risk (check other_series.do)
A14: UK | B14: mrkt_vol_uk | C14: MSCI UK indexrealized volatility in the quarter | D14: Refinitiv + own computation | E14: 1970Q2-2024Q4 | F14: David's paper
A15: ALL | B15: mrkvols&p | C15: S&P500 realized volatility in the quarter | D15: Refinitiv + own computation | E15: 1970Q2-2024Q4 | F15: David's paper
A16: ALL | B16: g4oil | C16: y-o-y growth in quarterly oil price | D16: FRED | E16: 1988Q3-2025Q3 | F16: https://fred.stlouisfed.org/series/MCOILBRENTEU#
A17: ALL | B17: oil | C17: Crude Oil Prices: Brent - Europe | D17: FRED | E17: 1972Q1-2025Q3 | F17: extendend with oil sheet from GaRDataRaw pre-1987q3
A18: ALL | B18: g4oil_long | C18: y-o-y growth in quarterly oil price | D18: own computations | E18: 1973Q1-2025Q3
A19: ALL | B19: chicago_fed_nfci | C19: Chicago Fed National Financial Conditions Index (NFCI) | D19: FRED | E19: 1971Q1-2025Q3 | F19: https://fred.stlouisfed.org/graph/?g=k5Pf
A20: ALL | B20: global_gdp | C20: Quarterly real GDP growth - OECD countries | D20: OECD | E20: 1970Q1-2025Q2 | F20: https://data-explorer.oecd.org/vis?df[ds]=DisseminateFinalDMZ&df[id]=DSD_NAMAIN1%40DF_QNA_EXPENDITURE_GROWTH_OECD&df[ag]=OECD.SDD.NAD&dq=Q..OECD.S1..B1GQ......GY.&pd=1962-Q1%2C&to[TIME_PERIOD]=false&vw=tb || growrh over 1 year || a note: formerly this variable relates to G7 countries. We have extended to full OECD
A21: UK | B21: global_credit | C21: weighted average of delta 3y credit over gdp (d3y_cre_to_gdp_all_ALL_ctry) using export as weights | D21: own computations | E21: 1973Q1-2025Q1
A22: UK | B22: pmi_out | C22: PMI output | D22: provided by BOE | E22: 1989Q4-2025Q3 | F22: we spliced the PMI output series using consensus GDP forecast. We regress the PMI on consensus GDP forecast (next calendar year), we store the coefficents and we backast the variables
A23: UK | B23: pmi_out_fut | C23: PMI output future | D23: provided by BOE | E23: 1989Q4-2025Q3 | F23: we spliced the PMI output future series using consensus GDP forecast. We regress the PMI on consensus GDP forecast (next calendar year), we store the coefficents and we backast the variables
A24: UK | B24: ciss_uk | C24: NEW CISS - Composite Indicator of Systemic Stress., United Kingdom, Daily | D24: ECB | E24: 1980Q1-2025Q3 | F24: https://data.ecb.europa.eu/data/datasets/CISS/CISS.D.GB.Z0Z.4F.EC.SS_CIN.IDX?chart_props=W3sibm9kZUlkIjoiMTA2NTQwMyIsInByb3BlcnRpZXMiOlt7ImNvbG9ySGV4IjoiIiwiY29sb3JUeXBlIjoiIiwiY2hhcnRUeXBlIjoibGluZWNoYXJ0IiwibGluZVN0eWxlIjoiU29saWQiLCJsaW5lV2lkdGgiOiIxLjUiLCJheGlzUG9zaXRpb24iOiJsZWZ0Iiwib2JzZXJ2YXRpb25WYWx1ZSI6ZmFsc2UsImRhdGVzIjpbXSwiaXNUZGF0YSI6dHJ1ZSwibW9kaWZpZWRVbml0VHlwZSI6Im5vbmUiLCJ5ZWFyIjoiZGF0ZXdpc2UiLCJzdGFydERhdGUiOiIxOTgwLTAxLTAyIiwiZW5kRGF0ZSI6IjIwMjUtMDctMDgiLCJzZXREYXRlIjp0cnVlLCJzaG93VGFibGVEYXRhIjpmYWxzZSwiY2hhbmdlTW9kZSI6ZmFsc2UsInNob3dNZW51U3R5bGVDaGFydCI6ZmFsc2UsImRpc3BsYXlNb2JpbGVDaGFydCI6dHJ1ZSwic2NyZWVuU2l6ZSI6Im1heCIsInNjcmVlbldpZHRoIjoyNTYwLCJzaG93VGRhdGEiOnRydWUsInRyYW5zZm9ybWVkRnJlcXVlbmN5IjoicXVhcnRlcmx5IiwidHJhbnNmb3JtZWRVbml0Ijoibm9uZSIsImZyZXF1ZW5jeSI6InF1YXJ0ZXJseSIsInVuaXQiOiJub25lIiwibW9kaWZpZWQiOiJ0cnVlIiwic2VyaWVzS2V5IjoiZGFpbHkiLCJzaG93dGFibGVTdGF0ZUJlZm9yZU1heFNjcmVlbiI6ZmFsc2UsImlzZGF0YWNvbXBhcmlzb24iOmZhbHNlLCJzZXJpZXNGcmVxdWVuY3kiOiJkYWlseSIsImludGlhbFNlcmllc0ZyZXF1ZW5jeSI6ImRhaWx5IiwibWV0YWRhdGFEZWNpbWFsIjoiNCIsImlzVGFibGVTb3J0ZWQiOmZhbHNlLCJpc1llYXJseVRkYXRhIjp0cnVlLCJyZXNwb25zZURhdGFFbmREYXRlIjoiIiwiaXNpbml0aWFsQ2hhcnREYXRhIjp0cnVlLCJpc0RhdGVzRnJvbURhdGVQaWNrZXIiOnRydWUsImRhdGVQaWNrZXJFbmREYXRlIjoiIiwiaXNEYXRlUGlja2VyRW5kRGF0ZSI6ZmFsc2UsInNlcmllc2tleVNldCI6IkNJU1MuRC5HQi5aMFouNEYuRUMuU1NfQ0lOLklEWHwyMzZ8bm9uZXxxdWFydGVybHl8bm9uZXxRdWFydGVybHkiLCJkYXRhc2V0SWQiOiIyMzYiLCJpc0NhbGxiYWNrIjpmYWxzZSwiaXNTbGlkZXJUZGF0YSI6ZmFsc2UsImlzU2xpZGVyRGF0YSI6dHJ1ZSwiaXNJbml0aWFsQ2hhcnREYXRhRnJvbUdyYXBoIjp0cnVlLCJjaGFydFNlcmllc0tleSI6IkNJU1MuRC5HQi5aMFouNEYuRUMuU1NfQ0lOLklEWCIsInR5cGVPZiI6IiJ9XX1d
A25: UK | B25: yield_curve_slope | C25: Difference between zero-coupon nominal spot 10 year yield and zero-coupon nominal spot 1 year yield | D25: BOE | E25: 1979Q1-2025Q3 | F25: https://www.bankofengland.co.uk/statistics/yield-curves Archive yield curve data Daily | Data are available in multiple vintages at the daily level - we generate quarterly data as the average of the average value for the days in the quarter (see other_series.do). We did not use monthly data as they referer to the last day in the month
A26: UK | B26: inflation_expectations | C26: CPI expectations in next calendar year | D26: Consensus Economics | E26: 1970Q1-2025Q3 | F26: the starting point is the seires used in the monthly analysis sheet infl1_m (IaRDataRaw_monthly.xlsx). We aggregate the series at the quarterly level (see other_series.do) - then we use g4infl to backast the series up to 1970q1. We regress inflation expectations on inflation from 1989q4 to 2024q4. We store the coefficents and we backast the series for inflation expectations
A27: UK | B27: import_deflator_fuel | C27: UK BOP: IMPORTS - FUELS - WORLD (IMPLIED DEFLATOR) | D27: ONS | E27: 1980Q1-2025Q2 | F27: ONS series is available only from 1997Q1 For the previous period we use Oxford economic UK IMPORT PRICE DEFLATOR - FUELS SADJ (it is exactly the same series as the ONS one post 1997 so there is no need to splice. The Oxford econ series has been downloaded from refinitiv datastream (the series name in datastream are: "UKXPMFU.E,UKBPGCQ.G")
A28: UK | B28: g4_import_deflator_fuel | C28: y-o-y growth in import fuels deflator | D28: own computations | E28: 1980Q1-2025Q2 | F28: for the first 4 quarters we use the value of 1981Q1
A29: UK | B29: mgdp_yoy | C29: y-o-y growth in monthly GDP | D29: OECD | E29: 1981Q2-2025Q2 | F29: https://www.ons.gov.uk/economy/grossdomesticproductgdp/datasets/gdpmonthlyestimateuktimeseriesdataset | Note: we compute this measure for a given quarter t as the growth rate between the average monhtly GPD of the first two months of the quarter and the average monthly GDP of the three months in the same quarter the previous year. ONS series is available from 1997q1 onward (hence the y-o-y growth from 1998q1).For the period before that we spliced the series with y-o-y gdp growth (see spliced_mgdp). Final note: we shift the period one quarter FORWARD to mimic the info set of the BOE. For a given quarter I already know the GDP for the first two months of the following one
A30: UK | B30: epu_idx | C30: UK Monthly EPU Index | D30: Economic Policy Uncertainty | E30: 1970Q1-2025Q3 | F30: Economic Policy Uncertainty Index | we spliced the monthly UK EPU with the historical one (see the epu_index.xlsx in data --> other series) | then we compute the quarterly series by taking the average of the months in the quarter
A31: UK | B31: house_price_growth | C31: United Kingdom - Selected residential property prices, Real, Year-on-year changes, in per cent | D31: BIS | E31: 1970Q1-2025Q2 | F31: https://data.bis.org/topics/RPP/BIS,WS_SPP,1.0/Q.GB.R.771
A32: UK | B32: housing_approvals | C32: Monthly number of total sterling approvals for house pruchase to individuals seasonally adj | D32: BOE | E32: 1970Q1-2025Q2 | F32: LPMVTVX | Bank of England | Database | the series is available monthly, WE sum the monthly series in the quarter. Then we spliced it with real 1y growth house price (look at spliced_housing_approvals)
A34: UK | B34: uk_export_weight | C34: From the excel file ExportWeights.xlsx | D34: provided by BOE | E34: 1970Q1-2025Q3 | F34: we use the sheet UK_X. For the quarters prior to 1972 we use the value of 1972. For the quarters after 2018 we use the value of 2018
A35: ALL | B35: credit_to_gdp_ALL_ctry | C35: AUS CAN FRA GER ITA SPAIN SWE SWI UK US - Credit from All sectors to Private non-financial sector at Market value, Percentage of GDP, Adjusted for breaks | D35: BIS | E35: 1970Q1-2025Q1 | F35: https://data.bis.org/topics/TOTAL_CREDIT/BIS,WS_TC,2.0/Q.GB.P.B.M.770.A
A36: ALL | B36: d3y_cre_to_gdp_all_ALL_ctry | C36: delta 3y - AUS CAN FRA GER ITA SPAIN SWE SWI UK US - Credit from All sectors to Private non-financial sector at Market value, Percentage of GDP, Adjusted for breaks | D36: own computations | E36: 1973Q1-2025Q1
A37: UK | B37: quarterly_pmi | C37: PMI for output and future output | D37: provided by BOE | E37: 1997Q2-2025Q3 | F37: The original series is available at the monthly level. We aggregte it at the quarterly level by computing the average in the quarter (see stata code \Codes\intermediate_codes -->other_series.do)
A38: UK | B38: gdp_growth_forecast_consensus | C38: Consensus forecast for current and next calendar year | D38: provided by BOE | E38: 1989Q4-2022Q4 | F38: The original series is available at the monthly level. We aggregte it at the quarterly level by computing the average in the quarter (see stata code \Codes\intermediate_codes -->other_series.do)

Sheet rgdp
B1: UK | C1: US | D1: EA
A2: 1970q1 | B2: 225223 | C2: 123456789 | D2: 123456789
A3: 1970q2 | B3: 230605 | C3: 123456789 | D3: 123456789
A4: 1970q3 | B4: 232800 | C4: 123456789 | D4: 123456789
A5: 1970q4 | B5: 234954 | C5: 123456789 | D5: 123456789
A6: 1971q1 | B6: 233843 | C6: 123456789 | D6: 123456789
A7: 1971q2 | B7: 238030 | C7: 123456789 | D7: 123456789
A8: 1971q3 | B8: 242078 | C8: 123456789 | D8: 123456789
A9: 1971q4 | B9: 243009 | C9: 123456789 | D9: 123456789
A10: 1972q1 | B10: 243540 | C10: 123456789 | D10: 123456789
A11: 1972q2 | B11: 249966 | C11: 123456789 | D11: 123456789
A12: 1972q3 | B12: 250633 | C12: 123456789 | D12: 123456789
A13: 1972q4 | B13: 254524 | C13: 123456789 | D13: 123456789
... A226: 2026Q1 | B226: 705571 | C226: 123456789 | D226: 123456789

Sheet g4rgdp
B1: UK | C1: US | D1: EA
A2: 1970q1 | B2: 123456789 | C2: 123456789 | D2: 123456789
A3: 1970q2 | B3: 123456789 | C3: 123456789 | D3: 123456789
A4: 1970q3 | B4: 123456789 | C4: 123456789 | D4: 123456789
A5: 1970q4 | B5: 123456789 | C5: 123456789 | D5: 123456789
A6: 1971q1 | B6: =(LN(rgdp!B6) - LN(rgdp!B2))*100 -> 3.7558928 | C6: 123456789 | D6: 123456789
A7: 1971q2 | B7: =(LN(rgdp!B7) - LN(rgdp!B3))*100 -> 3.1690426 | C7: 123456789 | D7: 123456789
A8: 1971q3 | B8: =(LN(rgdp!B8) - LN(rgdp!B4))*100 -> 3.9080272 | C8: 123456789 | D8: 123456789
A9: 1971q4 | B9: =(LN(rgdp!B9) - LN(rgdp!B5))*100 -> 3.3708729 | C9: 123456789 | D9: 123456789
A10: 1972q1 | B10: =(LN(rgdp!B10) - LN(rgdp!B6))*100 -> 4.063125 | C10: 123456789 | D10: 123456789
A11: 1972q2 | B11: =(LN(rgdp!B11) - LN(rgdp!B7))*100 -> 4.8928192 | C11: 123456789 | D11: 123456789
A12: 1972q3 | B12: =(LN(rgdp!B12) - LN(rgdp!B8))*100 -> 3.4729729 | C12: 123456789 | D12: 123456789
A13: 1972q4 | B13: =(LN(rgdp!B13) - LN(rgdp!B9))*100 -> 4.6296654 | C13: 123456789 | D13: 123456789
A14: 1973q1 | B14: =(LN(rgdp!B14) - LN(rgdp!B10))*100 -> 9.2023637 | C14: 123456789 | D14: 123456789
A15: 1973q2 | B15: =(LN(rgdp!B15) - LN(rgdp!B11))*100 -> 6.7873159 | C15: 123456789 | D15: 123456789
A16: 1973q3 | B16: =(LN(rgdp!B16) - LN(rgdp!B12))*100 -> 5.5834443 | C16: 123456789 | D16: 123456789
A17: 1973q4 | B17: =(LN(rgdp!B17) - LN(rgdp!B13))*100 -> 3.6512302 | C17: 123456789 | D17: 123456789
... A225: 2025q4 | B225: =(LN(rgdp!B225) - LN(rgdp!B221))*100 -> 0.94825639 | C225: 123456789 | D225: 123456789
A226: 2026q1 | B226: 0.948256 | C226: 123456789 | D226: 123456789

Sheet g4rgdp_first
A1: date | B1: UK
A2: 1970q1 | B2: 123456789
A3: 1970q2 | B3: 123456789
A4: 1970q3 | B4: 123456789
A5: 1970q4 | B5: 123456789
A6: 1971q1 | B6: 3.7558928
A7: 1971q2 | B7: 3.1690426
A8: 1971q3 | B8: 3.9080272
A9: 1971q4 | B9: 3.3708729
A10: 1972q1 | B10: 4.063125
A11: 1972q2 | B11: 4.8928192
A12: 1972q3 | B12: 3.4729729
A13: 1972q4 | B13: 4.6296654
... A226: 2026q1 | B226: 0.6

Sheet qoq_rgdp
B1: UK | C1: US | D1: EA
A2: 1970q1 | B2: 123456789 | C2: 123456789 | D2: 123456789
A3: 1970q2 | B3: =(LN(rgdp!B3)-LN(rgdp!B2))*100 -> 2.3615268 | C3: 123456789 | D3: 123456789
A4: 1970q3 | B4: =(LN(rgdp!B4)-LN(rgdp!B3))*100 -> 0.94734257 | C4: 123456789 | D4: 123456789
A5: 1970q4 | B5: =(LN(rgdp!B5)-LN(rgdp!B4))*100 -> 0.92100344 | C5: 123456789 | D5: 123456789
A6: 1971q1 | B6: =(LN(rgdp!B6)-LN(rgdp!B5))*100 -> -0.47398003 | C6: 123456789 | D6: 123456789
A7: 1971q2 | B7: =(LN(rgdp!B7)-LN(rgdp!B6))*100 -> 1.7746766 | C7: 123456789 | D7: 123456789
A8: 1971q3 | B8: =(LN(rgdp!B8)-LN(rgdp!B7))*100 -> 1.6863272 | C8: 123456789 | D8: 123456789
A9: 1971q4 | B9: =(LN(rgdp!B9)-LN(rgdp!B8))*100 -> 0.38384914 | C9: 123456789 | D9: 123456789
A10: 1972q1 | B10: =(LN(rgdp!B10)-LN(rgdp!B9))*100 -> 0.21827204 | C10: 123456789 | D10: 123456789
A11: 1972q2 | B11: =(LN(rgdp!B11)-LN(rgdp!B10))*100 -> 2.6043709 | C11: 123456789 | D11: 123456789
A12: 1972q3 | B12: =(LN(rgdp!B12)-LN(rgdp!B11))*100 -> 0.26648091 | C12: 123456789 | D12: 123456789
A13: 1972q4 | B13: =(LN(rgdp!B13)-LN(rgdp!B12))*100 -> 1.5405416 | C13: 123456789 | D13: 123456789
A14: 1973q1 | B14: =(LN(rgdp!B14)-LN(rgdp!B13))*100 -> 4.7909702 | C14: 123456789 | D14: 123456789
... A225: 2025q4 | B225: =(LN(rgdp!B225)-LN(rgdp!B224))*100 -> -0.069564826 | C225: 123456789 | D225: 123456789
A226: 2026q1 | B226: -0.06956 | C226: 123456789 | D226: 123456789

Sheet avg_g4rgdp
B1: UK | C1: US | D1: EA
A2: 1970q1 | B2: 123456789 | C2: 123456789 | D2: 123456789
A3: 1970q2 | B3: 123456789 | C3: 123456789 | D3: 123456789
A4: 1970q3 | B4: 123456789 | C4: 123456789 | D4: 123456789
A5: 1970q4 | B5: 123456789 | C5: 123456789 | D5: 123456789
A6: 1971q1 | B6: 123456789 | C6: 123456789 | D6: 123456789
A7: 1971q2 | B7: 123456789 | C7: 123456789 | D7: 123456789
A8: 1971q3 | B8: 123456789 | C8: 123456789 | D8: 123456789
A9: 1971q4 | B9: =AVERAGE(g4rgdp!B6:B9) -> 3.5509589 | C9: 123456789 | D9: 123456789
A10: 1972q1 | B10: =AVERAGE(g4rgdp!B7:B10) -> 3.6277669 | C10: 123456789 | D10: 123456789
A11: 1972q2 | B11: =AVERAGE(g4rgdp!B8:B11) -> 4.0587111 | C11: 123456789 | D11: 123456789
A12: 1972q3 | B12: =AVERAGE(g4rgdp!B9:B12) -> 3.9499475 | C12: 123456789 | D12: 123456789
A13: 1972q4 | B13: =AVERAGE(g4rgdp!B10:B13) -> 4.2646457 | C13: 123456789 | D13: 123456789
A14: 1973q1 | B14: =AVERAGE(g4rgdp!B11:B14) -> 5.5494553 | C14: 123456789 | D14: 123456789
A15: 1973q2 | B15: =AVERAGE(g4rgdp!B12:B15) -> 6.0230795 | C15: 123456789 | D15: 123456789
A16: 1973q3 | B16: =AVERAGE(g4rgdp!B13:B16) -> 6.5506973 | C16: 123456789 | D16: 123456789
A17: 1973q4 | B17: =AVERAGE(g4rgdp!B14:B17) -> 6.3060885 | C17: 123456789 | D17: 123456789
A18: 1974q1 | B18: =AVERAGE(g4rgdp!B15:B18) -> 3.017657 | C18: 123456789 | D18: 123456789
A19: 1974q2 | B19: =AVERAGE(g4rgdp!B16:B19) -> 0.64126025 | C19: 123456789 | D19: 123456789
A20: 1974q3 | B20: =AVERAGE(g4rgdp!B17:B20) -> -1.0520907 | C20: 123456789 | D20: 123456789
... A223: 2025q2 | B223: =AVERAGE(g4rgdp!B220:B223) -> 1.6101431 | C223: 123456789 | D223: 123456789
A224: 2025q3 | B224: 1.2668547 | C224: 123456789 | D224: 123456789
A225: 2025q4 | B225: 1.2668547 | C225: 123456789 | D225: 123456789
A226: 2026q1 | B226: 1.266855 | C226: 123456789 | D226: 123456789

Sheet g4infl
B1: UK | C1: US | D1: EA
A2: 1970q1 | B2: 5.0102728 | C2: 123456789 | D2: 123456789
A3: 1970q2 | B3: 5.8689632 | C3: 123456789 | D3: 123456789
A4: 1970q3 | B4: 6.8417077 | C4: 123456789 | D4: 123456789
A5: 1970q4 | B5: 7.7038182 | C5: 123456789 | D5: 123456789
A6: 1971q1 | B6: 8.5882079 | C6: 123456789 | D6: 123456789
A7: 1971q2 | B7: 9.8446789 | C7: 123456789 | D7: 123456789
A8: 1971q3 | B8: 10.113419 | C8: 123456789 | D8: 123456789
A9: 1971q4 | B9: 9.2129552 | C9: 123456789 | D9: 123456789
A10: 1972q1 | B10: 7.9540339 | C10: 123456789 | D10: 123456789
A11: 1972q2 | B11: 6.17795 | C11: 123456789 | D11: 123456789
A12: 1972q3 | B12: 6.4592298 | C12: 123456789 | D12: 123456789
A13: 1972q4 | B13: 7.7151517 | C13: 123456789 | D13: 123456789
... A226: 2026q1 | B226: 4.07 | C226: 123456789 | D226: 123456789

Sheet infl
B1: UK | C1: US | D1: EA
A2: 1970q1 | B2: 123456789 | C2: 123456789 | D2: 123456789
A3: 1970q2 | B3: 123456789 | C3: 123456789 | D3: 123456789
A4: 1970q3 | B4: 123456789 | C4: 123456789 | D4: 123456789
A5: 1970q4 | B5: 123456789 | C5: 123456789 | D5: 123456789
A6: 1971q1 | B6: 123456789 | C6: 123456789 | D6: 123456789
A7: 1971q2 | B7: 123456789 | C7: 123456789 | D7: 123456789
A8: 1971q3 | B8: 123456789 | C8: 123456789 | D8: 123456789
A9: 1971q4 | B9: 123456789 | C9: 123456789 | D9: 123456789
A10: 1972q1 | B10: 123456789 | C10: 123456789 | D10: 123456789
A11: 1972q2 | B11: 123456789 | C11: 123456789 | D11: 123456789
A12: 1972q3 | B12: 123456789 | C12: 123456789 | D12: 123456789
A13: 1972q4 | B13: 123456789 | C13: 123456789 | D13: 123456789
... A226: 2026q1 | B226: 4.1 | C226: 123456789 | D226: 123456789

Sheet credit_to_gdp_bank
B1: UK | C1: US | D1: EA
A2: 1970q1 | B2: 29.5 | C2: 123456789 | D2: 123456789
A3: 1970q2 | B3: 29.9 | C3: 123456789 | D3: 123456789
A4: 1970q3 | B4: 29.3 | C4: 123456789 | D4: 123456789
A5: 1970q4 | B5: 29 | C5: 123456789 | D5: 123456789
A6: 1971q1 | B6: 29.3 | C6: 123456789 | D6: 123456789
A7: 1971q2 | B7: 29.2 | C7: 123456789 | D7: 123456789
A8: 1971q3 | B8: 29 | C8: 123456789 | D8: 123456789
A9: 1971q4 | B9: 29.4 | C9: 123456789 | D9: 123456789
A10: 1972q1 | B10: 31.2 | C10: 123456789 | D10: 123456789
A11: 1972q2 | B11: 31.8 | C11: 123456789 | D11: 123456789
A12: 1972q3 | B12: 32.5 | C12: 123456789 | D12: 123456789
A13: 1972q4 | B13: 33.4 | C13: 123456789 | D13: 123456789
... A226: 2026q1 | B226: 74.4 | C226: 123456789 | D226: 123456789

Sheet credit_to_gdp_all
B1: UK | C1: US | D1: EA
A2: 1970q1 | B2: 58 | C2: 123456789 | D2: 123456789
A3: 1970q2 | B3: 59.4 | C3: 123456789 | D3: 123456789
A4: 1970q3 | B4: 57.5 | C4: 123456789 | D4: 123456789
A5: 1970q4 | B5: 58.6 | C5: 123456789 | D5: 123456789
A6: 1971q1 | B6: 56.9 | C6: 123456789 | D6: 123456789
A7: 1971q2 | B7: 55.2 | C7: 123456789 | D7: 123456789
A8: 1971q3 | B8: 56.2 | C8: 123456789 | D8: 123456789
A9: 1971q4 | B9: 57.2 | C9: 123456789 | D9: 123456789
A10: 1972q1 | B10: 60.6 | C10: 123456789 | D10: 123456789
A11: 1972q2 | B11: 61.3 | C11: 123456789 | D11: 123456789
A12: 1972q3 | B12: 64.7 | C12: 123456789 | D12: 123456789
A13: 1972q4 | B13: 65 | C13: 123456789 | D13: 123456789
... A226: 2026q1 | B226: 135.6 | C226: 123456789 | D226: 123456789

Sheet delta_3y_credit_to_gdp_all
B1: UK | C1: US | D1: EA
A2: 1970q1 | B2: 123456789 | C2: 123456789 | D2: 123456789
A3: 1970q2 | B3: 123456789 | C3: 123456789 | D3: 123456789
A4: 1970q3 | B4: 123456789 | C4: 123456789 | D4: 123456789
A5: 1970q4 | B5: 123456789 | C5: 123456789 | D5: 123456789
A6: 1971q1 | B6: 123456789 | C6: 123456789 | D6: 123456789
A7: 1971q2 | B7: 123456789 | C7: 123456789 | D7: 123456789
A8: 1971q3 | B8: 123456789 | C8: 123456789 | D8: 123456789
A9: 1971q4 | B9: 123456789 | C9: 123456789 | D9: 123456789
A10: 1972q1 | B10: 123456789 | C10: 123456789 | D10: 123456789
A11: 1972q2 | B11: 123456789 | C11: 123456789 | D11: 123456789
A12: 1972q3 | B12: 123456789 | C12: 123456789 | D12: 123456789
A13: 1972q4 | B13: 123456789 | C13: 123456789 | D13: 123456789
A14: 1973q1 | B14: =credit_to_gdp_all!B14-credit_to_gdp_all!B2 -> 6.2 | C14: 123456789 | D14: 123456789
A15: 1973q2 | B15: =credit_to_gdp_all!B15-credit_to_gdp_all!B3 -> 6.9 | C15: 123456789 | D15: 123456789
A16: 1973q3 | B16: =credit_to_gdp_all!B16-credit_to_gdp_all!B4 -> 8.5 | C16: 123456789 | D16: 123456789
A17: 1973q4 | B17: =credit_to_gdp_all!B17-credit_to_gdp_all!B5 -> 5.3 | C17: 123456789 | D17: 123456789
A18: 1974q1 | B18: =credit_to_gdp_all!B18-credit_to_gdp_all!B6 -> 8.1 | C18: 123456789 | D18: 123456789
A19: 1974q2 | B19: =credit_to_gdp_all!B19-credit_to_gdp_all!B7 -> 9.7 | C19: 123456789 | D19: 123456789
A20: 1974q3 | B20: =credit_to_gdp_all!B20-credit_to_gdp_all!B8 -> 7.9 | C20: 123456789 | D20: 123456789
A21: 1974q4 | B21: =credit_to_gdp_all!B21-credit_to_gdp_all!B9 -> 4.1 | C21: 123456789 | D21: 123456789
A22: 1975q1 | B22: =credit_to_gdp_all!B22-credit_to_gdp_all!B10 -> -1.1 | C22: 123456789 | D22: 123456789
A23: 1975q2 | B23: =credit_to_gdp_all!B23-credit_to_gdp_all!B11 -> -2 | C23: 123456789 | D23: 123456789
A24: 1975q3 | B24: =credit_to_gdp_all!B24-credit_to_gdp_all!B12 -> -8.2 | C24: 123456789 | D24: 123456789
A25: 1975q4 | B25: =credit_to_gdp_all!B25-credit_to_gdp_all!B13 -> -7.1 | C25: 123456789 | D25: 123456789
... A222: 2025q1 | B222: =credit_to_gdp_all!B222-credit_to_gdp_all!B210 -> -21.1 | C222: 123456789 | D222: 123456789
A223: 2025q2 | B223: -21.1 | C223: 123456789 | D223: 123456789
A224: 2025q3 | B224: -21.1 | C224: 123456789 | D224: 123456789
A225: 2025q4 | B225: -21.1 | C225: 123456789 | D225: 123456789
A226: 2026q1 | B226: -21.1 | C226: 123456789 | D226: 123456789

Sheet vix
B1: UK | C1: US | D1: EA
A2: 1970q1 | B2: 123456789 | C2: 123456789 | D2: 123456789
A3: 1970q2 | B3: 123456789 | C3: 123456789 | D3: 123456789
A4: 1970q3 | B4: =spliced_vix!E4 -> 21.595786 | C4: 123456789 | D4: 123456789
A5: 1970q4 | B5: =spliced_vix!E5 -> 15.175278 | C5: 123456789 | D5: 123456789
A6: 1971q1 | B6: =spliced_vix!E6 -> 11.803492 | C6: 123456789 | D6: 123456789
A7: 1971q2 | B7: =spliced_vix!E7 -> 13.311177 | C7: 123456789 | D7: 123456789
A8: 1971q3 | B8: =spliced_vix!E8 -> 18.546722 | C8: 123456789 | D8: 123456789
A9: 1971q4 | B9: =spliced_vix!E9 -> 19.043493 | C9: 123456789 | D9: 123456789
A10: 1972q1 | B10: =spliced_vix!E10 -> 11.343203 | C10: 123456789 | D10: 123456789
A11: 1972q2 | B11: =spliced_vix!E11 -> 12.323083 | C11: 123456789 | D11: 123456789
A12: 1972q3 | B12: =spliced_vix!E12 -> 12.810704 | C12: 123456789 | D12: 123456789
A13: 1972q4 | B13: =spliced_vix!E13 -> 13.403912 | C13: 123456789 | D13: 123456789
A14: 1973q1 | B14: =spliced_vix!E14 -> 18.145358 | C14: 123456789 | D14: 123456789
A15: 1973q2 | B15: =spliced_vix!E15 -> 25.884861 | C15: 123456789 | D15: 123456789
... A225: 2025q4 | B225: =spliced_vix!E225 -> 16.98 | C225: 123456789 | D225: 123456789
A226: 2026q1 | B226: 16.98 | C226: 123456789 | D226: 123456789

Sheet bond_spread
B1: UK | C1: US | D1: EA
A2: 1970q1 | B2: 139.3333 | C2: 123456789 | D2: 123456789
A3: 1970q2 | B3: 129.6667 | C3: 123456789 | D3: 123456789
A4: 1970q3 | B4: 130 | C4: 123456789 | D4: 123456789
A5: 1970q4 | B5: 112.3333 | C5: 123456789 | D5: 123456789
A6: 1971q1 | B6: 134.6667 | C6: 123456789 | D6: 123456789
A7: 1971q2 | B7: 129 | C7: 123456789 | D7: 123456789
A8: 1971q3 | B8: 112.3333 | C8: 123456789 | D8: 123456789
A9: 1971q4 | B9: 108.6667 | C9: 123456789 | D9: 123456789
A10: 1972q1 | B10: 84 | C10: 123456789 | D10: 123456789
A11: 1972q2 | B11: 80 | C11: 123456789 | D11: 123456789
A12: 1972q3 | B12: 78 | C12: 123456789 | D12: 123456789
A13: 1972q4 | B13: 83.33334 | C13: 123456789 | D13: 123456789
... A226: 2026q1 | B226: 88.19082 | C226: 123456789 | D226: 123456789

Sheet market_vol_uk
B1: UK | C1: US | D1: EA
A2: 1970q1 | B2: 123456789 | C2: 123456789 | D2: 123456789
A3: 1970q2 | B3: 1.760576 | C3: 123456789 | D3: 123456789
A4: 1970q3 | B4: 0.920302 | C4: 123456789 | D4: 123456789
A5: 1970q4 | B5: 0.9194848 | C5: 123456789 | D5: 123456789
A6: 1971q1 | B6: 1.075156 | C6: 123456789 | D6: 123456789
A7: 1971q2 | B7: 1.236534 | C7: 123456789 | D7: 123456789
A8: 1971q3 | B8: 1.090747 | C8: 123456789 | D8: 123456789
A9: 1971q4 | B9: 1.052805 | C9: 123456789 | D9: 123456789
A10: 1972q1 | B10: 0.8836466 | C10: 123456789 | D10: 123456789
A11: 1972q2 | B11: 0.9238148 | C11: 123456789 | D11: 123456789
A12: 1972q3 | B12: 0.9445159 | C12: 123456789 | D12: 123456789
A13: 1972q4 | B13: 0.6200079 | C13: 123456789 | D13: 123456789
... A226: 2026q1 | B226: 0.5601551 | C226: 123456789 | D226: 123456789

Sheet mrkvols&p
B1: UK | C1: US | D1: EA
A2: 1970q1 | B2: 123456789 | C2: 123456789 | D2: 123456789
A3: 1970q2 | B3: 1.386367 | C3: 123456789 | D3: 123456789
A4: 1970q3 | B4: 0.8534265 | C4: 123456789 | D4: 123456789
A5: 1970q4 | B5: 0.5996996 | C5: 123456789 | D5: 123456789
A6: 1971q1 | B6: 0.4664527 | C6: 123456789 | D6: 123456789
A7: 1971q2 | B7: 0.5260337 | C7: 123456789 | D7: 123456789
A8: 1971q3 | B8: 0.732933 | C8: 123456789 | D8: 123456789
A9: 1971q4 | B9: 0.7525645 | C9: 123456789 | D9: 123456789
A10: 1972q1 | B10: 0.4482629 | C10: 123456789 | D10: 123456789
A11: 1972q2 | B11: 0.486986 | C11: 123456789 | D11: 123456789
A12: 1972q3 | B12: 0.5062559 | C12: 123456789 | D12: 123456789
A13: 1972q4 | B13: 0.5296984 | C13: 123456789 | D13: 123456789
... A226: 2026q1 | B226: 0.6586093 | C226: 123456789 | D226: 123456789

Sheet g4oil
B1: UK | C1: US | D1: EA
A2: 1970q1 | B2: 123456789 | C2: 123456789 | D2: 123456789
A3: 1970q2 | B3: 123456789 | C3: 123456789 | D3: 123456789
A4: 1970q3 | B4: 123456789 | C4: 123456789 | D4: 123456789
A5: 1970q4 | B5: 123456789 | C5: 123456789 | D5: 123456789
A6: 1971q1 | B6: 123456789 | C6: 123456789 | D6: 123456789
A7: 1971q2 | B7: 123456789 | C7: 123456789 | D7: 123456789
A8: 1971q3 | B8: 123456789 | C8: 123456789 | D8: 123456789
A9: 1971q4 | B9: 123456789 | C9: 123456789 | D9: 123456789
A10: 1972q1 | B10: 123456789 | C10: 123456789 | D10: 123456789
A11: 1972q2 | B11: 123456789 | C11: 123456789 | D11: 123456789
A12: 1972q3 | B12: 123456789 | C12: 123456789 | D12: 123456789
A13: 1972q4 | B13: 123456789 | C13: 123456789 | D13: 123456789
... A226: 2026q1 | B226: -13.6 | C226: 123456789 | D226: 123456789

Sheet oil
B1: UK | C1: US | D1: EA
A2: 1970q1 | B2: 123456789 | C2: 123456789 | D2: 123456789
A3: 1970q2 | B3: 123456789 | C3: 123456789 | D3: 123456789
A4: 1970q3 | B4: 123456789 | C4: 123456789 | D4: 123456789
A5: 1970q4 | B5: 123456789 | C5: 123456789 | D5: 123456789
A6: 1971q1 | B6: 123456789 | C6: 123456789 | D6: 123456789
A7: 1971q2 | B7: 123456789 | C7: 123456789 | D7: 123456789
A8: 1971q3 | B8: 123456789 | C8: 123456789 | D8: 123456789
A9: 1971q4 | B9: 123456789 | C9: 123456789 | D9: 123456789
A10: 1972q1 | B10: 1.7794754 | C10: 123456789 | D10: 123456789
A11: 1972q2 | B11: 1.7794754 | C11: 123456789 | D11: 123456789
A12: 1972q3 | B12: 1.8800107 | C12: 123456789 | D12: 123456789
A13: 1972q4 | B13: 1.8800107 | C13: 123456789 | D13: 123456789
... A226: 2026q1 | B226: 68.96 | C226: 123456789 | D226: 123456789

Sheet g4oil_long
B1: UK | C1: US | D1: EA
A2: 1970q1 | B2: 123456789 | C2: 123456789 | D2: 123456789
A3: 1970q2 | B3: 123456789 | C3: 123456789 | D3: 123456789
A4: 1970q3 | B4: 123456789 | C4: 123456789 | D4: 123456789
A5: 1970q4 | B5: 123456789 | C5: 123456789 | D5: 123456789
A6: 1971q1 | B6: 123456789 | C6: 123456789 | D6: 123456789
A7: 1971q2 | B7: 123456789 | C7: 123456789 | D7: 123456789
A8: 1971q3 | B8: 123456789 | C8: 123456789 | D8: 123456789
A9: 1971q4 | B9: 123456789 | C9: 123456789 | D9: 123456789
A10: 1972q1 | B10: 123456789 | C10: 123456789 | D10: 123456789
A11: 1972q2 | B11: 123456789 | C11: 123456789 | D11: 123456789
A12: 1972q3 | B12: 123456789 | C12: 123456789 | D12: 123456789
A13: 1972q4 | B13: 123456789 | C13: 123456789 | D13: 123456789
A14: 1973q1 | B14: =(oil!B14/oil!B10-1)*100 -> 17.514124 | C14: 123456789 | D14: 123456789
A15: 1973q2 | B15: =(oil!B15/oil!B11-1)*100 -> 32.768362 | C15: 123456789 | D15: 123456789
A16: 1973q3 | B16: =(oil!B16/oil!B12-1)*100 -> 44.385027 | C16: 123456789 | D16: 123456789
A17: 1973q4 | B17: =(oil!B17/oil!B13-1)*100 -> 119.25134 | C17: 123456789 | D17: 123456789
A18: 1974q1 | B18: =(oil!B18/oil!B14-1)*100 -> 525 | C18: 123456789 | D18: 123456789
A19: 1974q2 | B19: =(oil!B19/oil!B15-1)*100 -> 351.06376 | C19: 123456789 | D19: 123456789
A20: 1974q3 | B20: =(oil!B20/oil!B16-1)*100 -> 270.37037 | C20: 123456789 | D20: 123456789
A21: 1974q4 | B21: =(oil!B21/oil!B17-1)*100 -> 151.21949 | C21: 123456789 | D21: 123456789
A22: 1975q1 | B22: =(oil!B22/oil!B18-1)*100 -> -19.846153 | C22: 123456789 | D22: 123456789
A23: 1975q2 | B23: =(oil!B23/oil!B19-1)*100 -> -1.6980983 | C23: 123456789 | D23: 123456789
A24: 1975q3 | B24: =(oil!B24/oil!B20-1)*100 -> 4.3000031 | C24: 123456789 | D24: 123456789
A25: 1975q4 | B25: =(oil!B25/oil!B21-1)*100 -> 1.553406 | C25: 123456789 | D25: 123456789
... A225: 2025q4 | B225: =(oil!B225/oil!B221-1)*100 -> -7.5727114 | C225: 123456789 | D225: 123456789
A226: 2026q1 | B226: -7.57271 | C226: 123456789 | D226: 123456789

Sheet chicago_fed_nfci
B1: UK | C1: US | D1: EA
A2: 1970q1 | B2: 123456789 | C2: 123456789 | D2: 123456789
A3: 1970q2 | B3: 123456789 | C3: 123456789 | D3: 123456789
A4: 1970q3 | B4: 123456789 | C4: 123456789 | D4: 123456789
A5: 1970q4 | B5: 123456789 | C5: 123456789 | D5: 123456789
A6: 1971q1 | B6: 0.79973 | C6: 123456789 | D6: 123456789
A7: 1971q2 | B7: 1.27451 | C7: 123456789 | D7: 123456789
A8: 1971q3 | B8: 1.59126 | C8: 123456789 | D8: 123456789
A9: 1971q4 | B9: 1.50662 | C9: 123456789 | D9: 123456789
A10: 1972q1 | B10: 0.71666 | C10: 123456789 | D10: 123456789
A11: 1972q2 | B11: 0.11249 | C11: 123456789 | D11: 123456789
A12: 1972q3 | B12: 0.14566 | C12: 123456789 | D12: 123456789
A13: 1972q4 | B13: -0.22369 | C13: 123456789 | D13: 123456789
... A226: 2026q1 | B226: -0.52879567 | C226: 123456789 | D226: 123456789

Sheet global_gdp
B1: UK | C1: US | D1: EA
A2: 1970q1 | B2: 4.0731673 | C2: 123456789 | D2: 123456789
A3: 1970q2 | B3: 4.1070519 | C3: 123456789 | D3: 123456789
A4: 1970q3 | B4: 4.154521 | C4: 123456789 | D4: 123456789
A5: 1970q4 | B5: 3.509103 | C5: 123456789 | D5: 123456789
A6: 1971q1 | B6: 3.5735927 | C6: 123456789 | D6: 123456789
A7: 1971q2 | B7: 3.5897091 | C7: 123456789 | D7: 123456789
A8: 1971q3 | B8: 3.5656042 | C8: 123456789 | D8: 123456789
A9: 1971q4 | B9: 4.0393907 | C9: 123456789 | D9: 123456789
A10: 1972q1 | B10: 4.7037798 | C10: 123456789 | D10: 123456789
A11: 1972q2 | B11: 5.3038451 | C11: 123456789 | D11: 123456789
A12: 1972q3 | B12: 5.2515232 | C12: 123456789 | D12: 123456789
A13: 1972q4 | B13: 6.5310569 | C13: 123456789 | D13: 123456789
... A226: 2026q1 | B226: 1.8335395 | C226: 123456789 | D226: 123456789

Sheet global_credit
B1: UK | C1: US | D1: EA
A2: 1970q1 | B2: 123456789 | C2: 123456789 | D2: 123456789
A3: 1970q2 | B3: 123456789 | C3: 123456789 | D3: 123456789
A4: 1970q3 | B4: 123456789 | C4: 123456789 | D4: 123456789
A5: 1970q4 | B5: 123456789 | C5: 123456789 | D5: 123456789
A6: 1971q1 | B6: 123456789 | C6: 123456789 | D6: 123456789
A7: 1971q2 | B7: 123456789 | C7: 123456789 | D7: 123456789
A8: 1971q3 | B8: 123456789 | C8: 123456789 | D8: 123456789
A9: 1971q4 | B9: 123456789 | C9: 123456789 | D9: 123456789
A10: 1972q1 | B10: 123456789 | C10: 123456789 | D10: 123456789
A11: 1972q2 | B11: 123456789 | C11: 123456789 | D11: 123456789
A12: 1972q3 | B12: 123456789 | C12: 123456789 | D12: 123456789
A13: 1972q4 | B13: 123456789 | C13: 123456789 | D13: 123456789
A14: 1973q1 | B14: =SUMPRODUCT(d3y_cre_to_gdp_all_ALL_ctry!B14:R14,uk_export_weight!B14:R14)/SUM(uk_export_weight!B14:R14) -> 4.180438 | C14: 123456789 | D14: 123456789
A15: 1973q2 | B15: =SUMPRODUCT(d3y_cre_to_gdp_all_ALL_ctry!B15:R15,uk_export_weight!B15:R15)/SUM(uk_export_weight!B15:R15) -> 4.8930319 | C15: 123456789 | D15: 123456789
A16: 1973q3 | B16: =SUMPRODUCT(d3y_cre_to_gdp_all_ALL_ctry!B16:R16,uk_export_weight!B16:R16)/SUM(uk_export_weight!B16:R16) -> 5.3447333 | C16: 123456789 | D16: 123456789
A17: 1973q4 | B17: =SUMPRODUCT(d3y_cre_to_gdp_all_ALL_ctry!B17:R17,uk_export_weight!B17:R17)/SUM(uk_export_weight!B17:R17) -> 4.6514074 | C17: 123456789 | D17: 123456789
A18: 1974q1 | B18: =SUMPRODUCT(d3y_cre_to_gdp_all_ALL_ctry!B18:R18,uk_export_weight!B18:R18)/SUM(uk_export_weight!B18:R18) -> 4.7403005 | C18: 123456789 | D18: 123456789
A19: 1974q2 | B19: =SUMPRODUCT(d3y_cre_to_gdp_all_ALL_ctry!B19:R19,uk_export_weight!B19:R19)/SUM(uk_export_weight!B19:R19) -> 4.5620524 | C19: 123456789 | D19: 123456789
A20: 1974q3 | B20: =SUMPRODUCT(d3y_cre_to_gdp_all_ALL_ctry!B20:R20,uk_export_weight!B20:R20)/SUM(uk_export_weight!B20:R20) -> 4.4059709 | C20: 123456789 | D20: 123456789
A21: 1974q4 | B21: =SUMPRODUCT(d3y_cre_to_gdp_all_ALL_ctry!B21:R21,uk_export_weight!B21:R21)/SUM(uk_export_weight!B21:R21) -> 1.9943919 | C21: 123456789 | D21: 123456789
A22: 1975q1 | B22: =SUMPRODUCT(d3y_cre_to_gdp_all_ALL_ctry!B22:R22,uk_export_weight!B22:R22)/SUM(uk_export_weight!B22:R22) -> 1.2330367 | C22: 123456789 | D22: 123456789
A23: 1975q2 | B23: =SUMPRODUCT(d3y_cre_to_gdp_all_ALL_ctry!B23:R23,uk_export_weight!B23:R23)/SUM(uk_export_weight!B23:R23) -> 0.21500381 | C23: 123456789 | D23: 123456789
A24: 1975q3 | B24: =SUMPRODUCT(d3y_cre_to_gdp_all_ALL_ctry!B24:R24,uk_export_weight!B24:R24)/SUM(uk_export_weight!B24:R24) -> -0.24933224 | C24: 123456789 | D24: 123456789
A25: 1975q4 | B25: =SUMPRODUCT(d3y_cre_to_gdp_all_ALL_ctry!B25:R25,uk_export_weight!B25:R25)/SUM(uk_export_weight!B25:R25) -> -0.0053142156 | C25: 123456789 | D25: 123456789
... A225: 2025q4 | B225: =SUMPRODUCT(d3y_cre_to_gdp_all_ALL_ctry!B225:R225,uk_export_weight!B225:R225)/SUM(uk_export_weight!B225:R225) -> -11.590124 | C225: 123456789 | D225: 123456789
A226: 2026q1 | B226: -11.5901 | C226: 123456789 | D226: 123456789

Sheet global_credit_level
B1: UK | C1: US | D1: EA
A2: 1970q1 | B2: 123456789 | C2: 123456789 | D2: 123456789
A3: 1970q2 | B3: 123456789 | C3: 123456789 | D3: 123456789
A4: 1970q3 | B4: 123456789 | C4: 123456789 | D4: 123456789
A5: 1970q4 | B5: 123456789 | C5: 123456789 | D5: 123456789
A6: 1971q1 | B6: 123456789 | C6: 123456789 | D6: 123456789
A7: 1971q2 | B7: 123456789 | C7: 123456789 | D7: 123456789
A8: 1971q3 | B8: 123456789 | C8: 123456789 | D8: 123456789
A9: 1971q4 | B9: 123456789 | C9: 123456789 | D9: 123456789
A10: 1972q1 | B10: 123456789 | C10: 123456789 | D10: 123456789
A11: 1972q2 | B11: 123456789 | C11: 123456789 | D11: 123456789
A12: 1972q3 | B12: 123456789 | C12: 123456789 | D12: 123456789
A13: 1972q4 | B13: 123456789 | C13: 123456789 | D13: 123456789
A14: 1973q1 | B14: =SUMPRODUCT(credit_to_gdp_ALL_ctry!B14:R14,uk_export_weight!B14:R14)/SUM(uk_export_weight!B14:R14) -> 98.407927 | C14: 123456789 | D14: 123456789
A15: 1973q2 | B15: =SUMPRODUCT(credit_to_gdp_ALL_ctry!B15:R15,uk_export_weight!B15:R15)/SUM(uk_export_weight!B15:R15) -> 99.090243 | C15: 123456789 | D15: 123456789
A16: 1973q3 | B16: =SUMPRODUCT(credit_to_gdp_ALL_ctry!B16:R16,uk_export_weight!B16:R16)/SUM(uk_export_weight!B16:R16) -> 99.0999 | C16: 123456789 | D16: 123456789
A17: 1973q4 | B17: =SUMPRODUCT(credit_to_gdp_ALL_ctry!B17:R17,uk_export_weight!B17:R17)/SUM(uk_export_weight!B17:R17) -> 99.513727 | C17: 123456789 | D17: 123456789
A18: 1974q1 | B18: =SUMPRODUCT(credit_to_gdp_ALL_ctry!B18:R18,uk_export_weight!B18:R18)/SUM(uk_export_weight!B18:R18) -> 98.922895 | C18: 123456789 | D18: 123456789
A19: 1974q2 | B19: =SUMPRODUCT(credit_to_gdp_ALL_ctry!B19:R19,uk_export_weight!B19:R19)/SUM(uk_export_weight!B19:R19) -> 99.406705 | C19: 123456789 | D19: 123456789
A20: 1974q3 | B20: =SUMPRODUCT(credit_to_gdp_ALL_ctry!B20:R20,uk_export_weight!B20:R20)/SUM(uk_export_weight!B20:R20) -> 99.216343 | C20: 123456789 | D20: 123456789
A21: 1974q4 | B21: =SUMPRODUCT(credit_to_gdp_ALL_ctry!B21:R21,uk_export_weight!B21:R21)/SUM(uk_export_weight!B21:R21) -> 97.883943 | C21: 123456789 | D21: 123456789
A22: 1975q1 | B22: =SUMPRODUCT(credit_to_gdp_ALL_ctry!B22:R22,uk_export_weight!B22:R22)/SUM(uk_export_weight!B22:R22) -> 97.585256 | C22: 123456789 | D22: 123456789
A23: 1975q2 | B23: =SUMPRODUCT(credit_to_gdp_ALL_ctry!B23:R23,uk_export_weight!B23:R23)/SUM(uk_export_weight!B23:R23) -> 97.829918 | C23: 123456789 | D23: 123456789
A24: 1975q3 | B24: =SUMPRODUCT(credit_to_gdp_ALL_ctry!B24:R24,uk_export_weight!B24:R24)/SUM(uk_export_weight!B24:R24) -> 97.588939 | C24: 123456789 | D24: 123456789
A25: 1975q4 | B25: =SUMPRODUCT(credit_to_gdp_ALL_ctry!B25:R25,uk_export_weight!B25:R25)/SUM(uk_export_weight!B25:R25) -> 99.005247 | C25: 123456789 | D25: 123456789
... A226: 2026q1 | B226: =SUMPRODUCT(credit_to_gdp_ALL_ctry!B226:R226,uk_export_weight!B226:R226)/SUM(uk_export_weight!B226:R226) -> 166.15522 | C226: 123456789 | D226: 123456789

Sheet global_credit_level_2y_gr
B1: UK | C1: US | D1: EA
A2: 1970q1 | B2: 123456789 | C2: 123456789 | D2: 123456789
A3: 1970q2 | B3: 123456789 | C3: 123456789 | D3: 123456789
A4: 1970q3 | B4: 123456789 | C4: 123456789 | D4: 123456789
A5: 1970q4 | B5: 123456789 | C5: 123456789 | D5: 123456789
A6: 1971q1 | B6: 123456789 | C6: 123456789 | D6: 123456789
A7: 1971q2 | B7: 123456789 | C7: 123456789 | D7: 123456789
A8: 1971q3 | B8: 123456789 | C8: 123456789 | D8: 123456789
A9: 1971q4 | B9: 123456789 | C9: 123456789 | D9: 123456789
A10: 1972q1 | B10: 123456789 | C10: 123456789 | D10: 123456789
A11: 1972q2 | B11: 123456789 | C11: 123456789 | D11: 123456789
A12: 1972q3 | B12: 123456789 | C12: 123456789 | D12: 123456789
A13: 1972q4 | B13: 123456789 | C13: 123456789 | D13: 123456789
A14: 1973q1 | C14: 123456789 | D14: 123456789
A15: 1973q2 | C15: 123456789 | D15: 123456789
A16: 1973q3 | C16: 123456789 | D16: 123456789
A17: 1973q4 | C17: 123456789 | D17: 123456789
A18: 1974q1 | C18: 123456789 | D18: 123456789
A19: 1974q2 | C19: 123456789 | D19: 123456789
A20: 1974q3 | C20: 123456789 | D20: 123456789
A21: 1974q4 | C21: 123456789 | D21: 123456789
A22: 1975q1 | B22: =(LN(global_credit_level!B22)-LN(global_credit_level!B14)) * 100 -> -0.83949339 | C22: 123456789 | D22: 123456789
A23: 1975q2 | B23: =(LN(global_credit_level!B23)-LN(global_credit_level!B15)) * 100 -> -1.2800532 | C23: 123456789 | D23: 123456789
A24: 1975q3 | B24: =(LN(global_credit_level!B24)-LN(global_credit_level!B16)) * 100 -> -1.5364279 | C24: 123456789 | D24: 123456789
A25: 1975q4 | B25: =(LN(global_credit_level!B25)-LN(global_credit_level!B17)) * 100 -> -0.51227411 | C25: 123456789 | D25: 123456789
A26: 1976q1 | B26: =(LN(global_credit_level!B26)-LN(global_credit_level!B18)) * 100 -> -1.7192153 | C26: 123456789 | D26: 123456789
A27: 1976q2 | B27: =(LN(global_credit_level!B27)-LN(global_credit_level!B19)) * 100 -> -2.220838 | C27: 123456789 | D27: 123456789
A28: 1976q3 | B28: =(LN(global_credit_level!B28)-LN(global_credit_level!B20)) * 100 -> -2.3296215 | C28: 123456789 | D28: 123456789
A29: 1976q4 | B29: =(LN(global_credit_level!B29)-LN(global_credit_level!B21)) * 100 -> -0.45929513 | C29: 123456789 | D29: 123456789
A30: 1977q1 | B30: =(LN(global_credit_level!B30)-LN(global_credit_level!B22)) * 100 -> -0.58296111 | C30: 123456789 | D30: 123456789
A31: 1977q2 | B31: =(LN(global_credit_level!B31)-LN(global_credit_level!B23)) * 100 -> -0.1678479 | C31: 123456789 | D31: 123456789
A32: 1977q3 | B32: =(LN(global_credit_level!B32)-LN(global_credit_level!B24)) * 100 -> 0.15210616 | C32: 123456789 | D32: 123456789
A33: 1977q4 | B33: =(LN(global_credit_level!B33)-LN(global_credit_level!B25)) * 100 -> 0.098213392 | C33: 123456789 | D33: 123456789
... A226: 2026q1 | B226: =(LN(global_credit_level!B226)-LN(global_credit_level!B218)) * 100 -> -1.9493369 | C226: 123456789 | D226: 123456789

Sheet pmi_out
B1: UK | C1: US | D1: EA
A2: 1970q1 | B2: 123456789 | C2: 123456789 | D2: 123456789
A3: 1970q2 | B3: 123456789 | C3: 123456789 | D3: 123456789
A4: 1970q3 | B4: 123456789 | C4: 123456789 | D4: 123456789
A5: 1970q4 | B5: 123456789 | C5: 123456789 | D5: 123456789
A6: 1971q1 | B6: 123456789 | C6: 123456789 | D6: 123456789
A7: 1971q2 | B7: 123456789 | C7: 123456789 | D7: 123456789
A8: 1971q3 | B8: 123456789 | C8: 123456789 | D8: 123456789
A9: 1971q4 | B9: 123456789 | C9: 123456789 | D9: 123456789
A10: 1972q1 | B10: 123456789 | C10: 123456789 | D10: 123456789
A11: 1972q2 | B11: 123456789 | C11: 123456789 | D11: 123456789
A12: 1972q3 | B12: 123456789 | C12: 123456789 | D12: 123456789
A13: 1972q4 | B13: 123456789 | C13: 123456789 | D13: 123456789
... A80: 1989q3 | B80: 123456789 | C80: 123456789 | D80: 123456789
A81: 1989q4 | B81: =spliced_quartely_pmi!D81 -> 52.536467 | C81: 123456789 | D81: 123456789
A82: 1990q1 | B82: =spliced_quartely_pmi!D82 -> 54.156892 | C82: 123456789 | D82: 123456789
A83: 1990q2 | B83: =spliced_quartely_pmi!D83 -> 55.090246 | C83: 123456789 | D83: 123456789
A84: 1990q3 | B84: =spliced_quartely_pmi!D84 -> 54.285789 | C84: 123456789 | D84: 123456789
A85: 1990q4 | B85: =spliced_quartely_pmi!D85 -> 50.240485 | C85: 123456789 | D85: 123456789
A86: 1991q1 | B86: =spliced_quartely_pmi!D86 -> 54.551639 | C86: 123456789 | D86: 123456789
A87: 1991q2 | B87: =spliced_quartely_pmi!D87 -> 54.524018 | C87: 123456789 | D87: 123456789
A88: 1991q3 | B88: =spliced_quartely_pmi!D88 -> 53.328267 | C88: 123456789 | D88: 123456789
A89: 1991q4 | B89: =spliced_quartely_pmi!D89 -> 53.347829 | C89: 123456789 | D89: 123456789
A90: 1992q1 | B90: =spliced_quartely_pmi!D90 -> 55.435506 | C90: 123456789 | D90: 123456789
A91: 1992q2 | B91: =spliced_quartely_pmi!D91 -> 55.223748 | C91: 123456789 | D91: 123456789
A92: 1992q3 | B92: =spliced_quartely_pmi!D92 -> 53.03019 | C92: 123456789 | D92: 123456789
... A224: 2025q3 | B224: =spliced_quartely_pmi!D224 -> 51.67 | C224: 123456789 | D224: 123456789
A225: 2025q4 | B225: 51.67 | C225: 123456789 | D225: 123456789
A226: 2026q1 | B226: 51.67 | C226: 123456789 | D226: 123456789

Sheet pmi_out_long
B1: UK | C1: US | D1: EA
A2: 1970q1 | B2: 123456789 | C2: 123456789 | D2: 123456789
A3: 1970q2 | B3: 123456789 | C3: 123456789 | D3: 123456789
A4: 1970q3 | B4: 123456789 | C4: 123456789 | D4: 123456789
A5: 1970q4 | B5: 123456789 | C5: 123456789 | D5: 123456789
A6: 1971q1 | B6: =spliced_quartely_pmi_long!D6 -> 56.070287 | C6: 123456789 | D6: 123456789
A7: 1971q2 | B7: =spliced_quartely_pmi_long!D7 -> 55.457302 | C7: 123456789 | D7: 123456789
A8: 1971q3 | B8: =spliced_quartely_pmi_long!D8 -> 56.229196 | C8: 123456789 | D8: 123456789
A9: 1971q4 | B9: =spliced_quartely_pmi_long!D9 -> 55.668121 | C9: 123456789 | D9: 123456789
A10: 1972q1 | B10: =spliced_quartely_pmi_long!D10 -> 56.391201 | C10: 123456789 | D10: 123456789
A11: 1972q2 | B11: =spliced_quartely_pmi_long!D11 -> 57.257845 | C11: 123456789 | D11: 123456789
A12: 1972q3 | B12: =spliced_quartely_pmi_long!D12 -> 55.774768 | C12: 123456789 | D12: 123456789
A13: 1972q4 | B13: =spliced_quartely_pmi_long!D13 -> 56.982972 | C13: 123456789 | D13: 123456789
A14: 1973q1 | B14: =spliced_quartely_pmi_long!D14 -> 61.759308 | C14: 123456789 | D14: 123456789
A15: 1973q2 | B15: =spliced_quartely_pmi_long!D15 -> 59.23671 | C15: 123456789 | D15: 123456789
A16: 1973q3 | B16: =spliced_quartely_pmi_long!D16 -> 57.979226 | C16: 123456789 | D16: 123456789
A17: 1973q4 | B17: =spliced_quartely_pmi_long!D17 -> 55.960963 | C17: 123456789 | D17: 123456789
... A224: 2025q3 | B224: =spliced_quartely_pmi_long!D224 -> 51.67 | C224: 123456789 | D224: 123456789
A225: 2025q4 | B225: 51.67 | C225: 123456789 | D225: 123456789
A226: 2026q1 | B226: 51.67 | C226: 123456789 | D226: 123456789

Sheet pmi_out_fut_long
B1: UK | C1: US | D1: EA
A2: 1970q1 | B2: 123456789 | C2: 123456789 | D2: 123456789
A3: 1970q2 | B3: 123456789 | C3: 123456789 | D3: 123456789
A4: 1970q3 | B4: 123456789 | C4: 123456789 | D4: 123456789
A5: 1970q4 | B5: 123456789 | C5: 123456789 | D5: 123456789
A6: 1971q1 | B6: =spliced_quartely_pmi_long!G6 -> 70.100758 | C6: 123456789 | D6: 123456789
A7: 1971q2 | B7: =spliced_quartely_pmi_long!G7 -> 69.323792 | C7: 123456789 | D7: 123456789
A8: 1971q3 | B8: =spliced_quartely_pmi_long!G8 -> 70.302178 | C8: 123456789 | D8: 123456789
A9: 1971q4 | B9: =spliced_quartely_pmi_long!G9 -> 69.591008 | C9: 123456789 | D9: 123456789
A10: 1972q1 | B10: =spliced_quartely_pmi_long!G10 -> 70.507522 | C10: 123456789 | D10: 123456789
A11: 1972q2 | B11: =spliced_quartely_pmi_long!G11 -> 71.606004 | C11: 123456789 | D11: 123456789
A12: 1972q3 | B12: =spliced_quartely_pmi_long!G12 -> 69.726184 | C12: 123456789 | D12: 123456789
A13: 1972q4 | B13: =spliced_quartely_pmi_long!G13 -> 71.257599 | C13: 123456789 | D13: 123456789
A14: 1973q1 | B14: =spliced_quartely_pmi_long!G14 -> 77.311669 | C14: 123456789 | D14: 123456789
A15: 1973q2 | B15: =spliced_quartely_pmi_long!G15 -> 74.114242 | C15: 123456789 | D15: 123456789
A16: 1973q3 | B16: =spliced_quartely_pmi_long!G16 -> 72.520364 | C16: 123456789 | D16: 123456789
A17: 1973q4 | B17: =spliced_quartely_pmi_long!G17 -> 69.962189 | C17: 123456789 | D17: 123456789
... A224: 2025q3 | B224: =spliced_quartely_pmi_long!G224 -> 66.791365 | C224: 123456789 | D224: 123456789
A225: 2025q4 | B225: 66.79 | C225: 123456789 | D225: 123456789
A226: 2026q1 | B226: 66.79 | C226: 123456789 | D226: 123456789

Sheet pmi_out_fut
B1: UK | C1: US | D1: EA
A2: 1970q1 | B2: 123456789 | C2: 123456789 | D2: 123456789
A3: 1970q2 | B3: 123456789 | C3: 123456789 | D3: 123456789
A4: 1970q3 | B4: 123456789 | C4: 123456789 | D4: 123456789
A5: 1970q4 | B5: 123456789 | C5: 123456789 | D5: 123456789
A6: 1971q1 | B6: 123456789 | C6: 123456789 | D6: 123456789
A7: 1971q2 | B7: 123456789 | C7: 123456789 | D7: 123456789
A8: 1971q3 | B8: 123456789 | C8: 123456789 | D8: 123456789
A9: 1971q4 | B9: 123456789 | C9: 123456789 | D9: 123456789
A10: 1972q1 | B10: 123456789 | C10: 123456789 | D10: 123456789
A11: 1972q2 | B11: 123456789 | C11: 123456789 | D11: 123456789
A12: 1972q3 | B12: 123456789 | C12: 123456789 | D12: 123456789
A13: 1972q4 | B13: 123456789 | C13: 123456789 | D13: 123456789
... A80: 1989q3 | B80: 123456789 | C80: 123456789 | D80: 123456789
A81: 1989q4 | B81: =spliced_quartely_pmi!G81 -> 65.448229 | C81: 123456789 | D81: 123456789
A82: 1990q1 | B82: =spliced_quartely_pmi!G82 -> 67.688822 | C82: 123456789 | D82: 123456789
A83: 1990q2 | B83: =spliced_quartely_pmi!G83 -> 68.979388 | C83: 123456789 | D83: 123456789
A84: 1990q3 | B84: =spliced_quartely_pmi!G84 -> 67.867049 | C84: 123456789 | D84: 123456789
A85: 1990q4 | B85: =spliced_quartely_pmi!G85 -> 62.27353 | C85: 123456789 | D85: 123456789
A86: 1991q1 | B86: =spliced_quartely_pmi!G86 -> 68.234646 | C86: 123456789 | D86: 123456789
A87: 1991q2 | B87: =spliced_quartely_pmi!G87 -> 68.196454 | C87: 123456789 | D87: 123456789
A88: 1991q3 | B88: =spliced_quartely_pmi!G88 -> 66.543066 | C88: 123456789 | D88: 123456789
A89: 1991q4 | B89: =spliced_quartely_pmi!G89 -> 66.570115 | C89: 123456789 | D89: 123456789
A90: 1992q1 | B90: =spliced_quartely_pmi!G90 -> 69.456786 | C90: 123456789 | D90: 123456789
A91: 1992q2 | B91: =spliced_quartely_pmi!G91 -> 69.163983 | C91: 123456789 | D91: 123456789
A92: 1992q3 | B92: =spliced_quartely_pmi!G92 -> 66.130909 | C92: 123456789 | D92: 123456789
... A224: 2025q3 | B224: =spliced_quartely_pmi!G224 -> 66.791365 | C224: 123456789 | D224: 123456789
A225: 2025q4 | B225: 66.79 | C225: 123456789 | D225: 123456789

Sheet ciss_uk
B1: UK | C1: US | D1: EA
A2: 1970q1 | B2: 123456789 | C2: 123456789 | D2: 123456789
A3: 1970q2 | B3: 123456789 | C3: 123456789 | D3: 123456789
A4: 1970q3 | B4: 123456789 | C4: 123456789 | D4: 123456789
A5: 1970q4 | B5: 123456789 | C5: 123456789 | D5: 123456789
A6: 1971q1 | B6: 123456789 | C6: 123456789 | D6: 123456789
A7: 1971q2 | B7: 123456789 | C7: 123456789 | D7: 123456789
A8: 1971q3 | B8: 123456789 | C8: 123456789 | D8: 123456789
A9: 1971q4 | B9: 123456789 | C9: 123456789 | D9: 123456789
A10: 1972q1 | B10: 123456789 | C10: 123456789 | D10: 123456789
A11: 1972q2 | B11: 123456789 | C11: 123456789 | D11: 123456789
A12: 1972q3 | B12: 123456789 | C12: 123456789 | D12: 123456789
A13: 1972q4 | B13: 123456789 | C13: 123456789 | D13: 123456789
... A226: 2026Q1 | B226: 0.0253 | C226: 123456789 | D226: 123456789

Sheet yield_curve_slope
B1: UK | C1: US | D1: EA
A2: 1970q1 | B2: 123456789 | C2: 123456789 | D2: 123456789
A3: 1970q2 | B3: 123456789 | C3: 123456789 | D3: 123456789
A4: 1970q3 | B4: 123456789 | C4: 123456789 | D4: 123456789
A5: 1970q4 | B5: 123456789 | C5: 123456789 | D5: 123456789
A6: 1971q1 | B6: 123456789 | C6: 123456789 | D6: 123456789
A7: 1971q2 | B7: 123456789 | C7: 123456789 | D7: 123456789
A8: 1971q3 | B8: 123456789 | C8: 123456789 | D8: 123456789
A9: 1971q4 | B9: 123456789 | C9: 123456789 | D9: 123456789
A10: 1972q1 | B10: 123456789 | C10: 123456789 | D10: 123456789
A11: 1972q2 | B11: 123456789 | C11: 123456789 | D11: 123456789
A12: 1972q3 | B12: 123456789 | C12: 123456789 | D12: 123456789
A13: 1972q4 | B13: 123456789 | C13: 123456789 | D13: 123456789
... A226: 2026q1 | B226: 0.92551168 | C226: 123456789 | D226: 123456789

Sheet inflation_expectations
B1: UK | C1: US | D1: EA
A2: 1970q1 | B2: =spliced_inflation_expectations!D2 -> 3.1158753 | C2: 123456789 | D2: 123456789
A3: 1970q2 | B3: =spliced_inflation_expectations!D3 -> 3.4165041 | C3: 123456789 | D3: 123456789
A4: 1970q3 | B4: =spliced_inflation_expectations!D4 -> 3.7570635 | C4: 123456789 | D4: 123456789
A5: 1970q4 | B5: =spliced_inflation_expectations!D5 -> 4.0588898 | C5: 123456789 | D5: 123456789
A6: 1971q1 | B6: =spliced_inflation_expectations!D6 -> 4.368516 | C6: 123456789 | D6: 123456789
A7: 1971q2 | B7: =spliced_inflation_expectations!D7 -> 4.8084085 | C7: 123456789 | D7: 123456789
A8: 1971q3 | B8: =spliced_inflation_expectations!D8 -> 4.902495 | C8: 123456789 | D8: 123456789
A9: 1971q4 | B9: =spliced_inflation_expectations!D9 -> 4.5872411 | C9: 123456789 | D9: 123456789
A10: 1972q1 | B10: =spliced_inflation_expectations!D10 -> 4.1464907 | C10: 123456789 | D10: 123456789
A11: 1972q2 | B11: =spliced_inflation_expectations!D11 -> 3.5246809 | C11: 123456789 | D11: 123456789
A12: 1972q3 | B12: =spliced_inflation_expectations!D12 -> 3.6231574 | C12: 123456789 | D12: 123456789
A13: 1972q4 | B13: =spliced_inflation_expectations!D13 -> 4.0628577 | C13: 123456789 | D13: 123456789
... A224: 2025q3 | B224: =spliced_inflation_expectations!D224 -> 2.4864667 | C224: 123456789 | D224: 123456789
A225: 2025q4 | B225: 2.49 | C225: 123456789 | D225: 123456789
A226: 2026q1 | B226: 2.49 | C226: 123456789 | D226: 123456789

Sheet import_deflator_fuel
B1: UK | C1: US | D1: EA
A2: 1970q1 | B2: 123456789 | C2: 123456789 | D2: 123456789
A3: 1970q2 | B3: 123456789 | C3: 123456789 | D3: 123456789
A4: 1970q3 | B4: 123456789 | C4: 123456789 | D4: 123456789
A5: 1970q4 | B5: 123456789 | C5: 123456789 | D5: 123456789
A6: 1971q1 | B6: 123456789 | C6: 123456789 | D6: 123456789
A7: 1971q2 | B7: 123456789 | C7: 123456789 | D7: 123456789
A8: 1971q3 | B8: 123456789 | C8: 123456789 | D8: 123456789
A9: 1971q4 | B9: 123456789 | C9: 123456789 | D9: 123456789
A10: 1972q1 | B10: 123456789 | C10: 123456789 | D10: 123456789
A11: 1972q2 | B11: 123456789 | C11: 123456789 | D11: 123456789
A12: 1972q3 | B12: 123456789 | C12: 123456789 | D12: 123456789
A13: 1972q4 | B13: 123456789 | C13: 123456789 | D13: 123456789
... A226: 2026q1 | B226: 70.4 | C226: 123456789 | D226: 123456789

Sheet g4_import_deflator_fuel
B1: UK | C1: US | D1: EA
A2: 1970q1 | B2: 123456789 | C2: 123456789 | D2: 123456789
A3: 1970q2 | B3: 123456789 | C3: 123456789 | D3: 123456789
A4: 1970q3 | B4: 123456789 | C4: 123456789 | D4: 123456789
A5: 1970q4 | B5: 123456789 | C5: 123456789 | D5: 123456789
A6: 1971q1 | B6: 123456789 | C6: 123456789 | D6: 123456789
A7: 1971q2 | B7: 123456789 | C7: 123456789 | D7: 123456789
A8: 1971q3 | B8: 123456789 | C8: 123456789 | D8: 123456789
A9: 1971q4 | B9: 123456789 | C9: 123456789 | D9: 123456789
A10: 1972q1 | B10: 123456789 | C10: 123456789 | D10: 123456789
A11: 1972q2 | B11: 123456789 | C11: 123456789 | D11: 123456789
A12: 1972q3 | B12: 123456789 | C12: 123456789 | D12: 123456789
A13: 1972q4 | B13: 123456789 | C13: 123456789 | D13: 123456789
... A45: 1980q4 | B45: 23.278848 | C45: 123456789 | D45: 123456789
A46: 1981q1 | B46: =(import_deflator_fuel!B46/import_deflator_fuel!B42-1)*100 -> 23.278848 | C46: 123456789 | D46: 123456789
A47: 1981q2 | B47: =(import_deflator_fuel!B47/import_deflator_fuel!B43-1)*100 -> 20.142311 | C47: 123456789 | D47: 123456789
A48: 1981q3 | B48: =(import_deflator_fuel!B48/import_deflator_fuel!B44-1)*100 -> 29.856899 | C48: 123456789 | D48: 123456789
A49: 1981q4 | B49: =(import_deflator_fuel!B49/import_deflator_fuel!B45-1)*100 -> 30.562665 | C49: 123456789 | D49: 123456789
A50: 1982q1 | B50: =(import_deflator_fuel!B50/import_deflator_fuel!B46-1)*100 -> 27.375789 | C50: 123456789 | D50: 123456789
A51: 1982q2 | B51: =(import_deflator_fuel!B51/import_deflator_fuel!B47-1)*100 -> 13.194066 | C51: 123456789 | D51: 123456789
A52: 1982q3 | B52: =(import_deflator_fuel!B52/import_deflator_fuel!B48-1)*100 -> 8.8647395 | C52: 123456789 | D52: 123456789
A53: 1982q4 | B53: =(import_deflator_fuel!B53/import_deflator_fuel!B49-1)*100 -> 10.683395 | C53: 123456789 | D53: 123456789
A54: 1983q1 | B54: =(import_deflator_fuel!B54/import_deflator_fuel!B50-1)*100 -> 7.4071003 | C54: 123456789 | D54: 123456789
A55: 1983q2 | B55: =(import_deflator_fuel!B55/import_deflator_fuel!B51-1)*100 -> 6.9993786 | C55: 123456789 | D55: 123456789
A56: 1983q3 | B56: =(import_deflator_fuel!B56/import_deflator_fuel!B52-1)*100 -> 3.7753414 | C56: 123456789 | D56: 123456789
A57: 1983q4 | B57: =(import_deflator_fuel!B57/import_deflator_fuel!B53-1)*100 -> 0.43723199 | C57: 123456789 | D57: 123456789
... A225: 2025q4 | B225: =(import_deflator_fuel!B225/import_deflator_fuel!B221-1)*100 -> -14.146341 | C225: 123456789 | D225: 123456789
A226: 2026q1 | B226: -14.1463 | C226: 123456789 | D226: 123456789

Sheet mgdp_yoy
B1: UK | C1: US | D1: EA
A2: 1970q1 | B2: 123456789 | C2: 123456789 | D2: 123456789
A3: 1970q2 | B3: 123456789 | C3: 123456789 | D3: 123456789
A4: 1970q3 | B4: 123456789 | C4: 123456789 | D4: 123456789
A5: 1970q4 | B5: 123456789 | C5: 123456789 | D5: 123456789
A6: 1971q1 | B6: =spliced_mgdp!D7 -> 0.03229202 | C6: 123456789 | D6: 123456789
A7: 1971q2 | B7: =spliced_mgdp!D8 -> 0.039711773 | C7: 123456789 | D7: 123456789
A8: 1971q3 | B8: =spliced_mgdp!D9 -> 0.034318492 | C8: 123456789 | D8: 123456789
A9: 1971q4 | B9: =spliced_mgdp!D10 -> 0.041269027 | C9: 123456789 | D9: 123456789
A10: 1972q1 | B10: =spliced_mgdp!D11 -> 0.049599546 | C10: 123456789 | D10: 123456789
A11: 1972q2 | B11: =spliced_mgdp!D12 -> 0.035343623 | C11: 123456789 | D11: 123456789
A12: 1972q3 | B12: =spliced_mgdp!D13 -> 0.046957358 | C12: 123456789 | D12: 123456789
A13: 1972q4 | B13: =spliced_mgdp!D14 -> 0.092869392 | C13: 123456789 | D13: 123456789
A14: 1973q1 | B14: =spliced_mgdp!D15 -> 0.068621181 | C14: 123456789 | D14: 123456789
A15: 1973q2 | B15: =spliced_mgdp!D16 -> 0.056533745 | C15: 123456789 | D15: 123456789
A16: 1973q3 | B16: =spliced_mgdp!D17 -> 0.037133409 | C16: 123456789 | D16: 123456789
A17: 1973q4 | B17: =spliced_mgdp!D18 -> -0.039200183 | C17: 123456789 | D17: 123456789
... A223: 2025q2 | B223: =spliced_mgdp!D224 -> 0.013326752 | C223: 123456789 | D223: 123456789
A224: 2025q3 | B224: 0.013326752 | C224: 123456789 | D224: 123456789
A225: 2025q4 | B225: 0.0092 | C225: 123456789 | D225: 123456789
A226: 2026q1 | B226: 0.0092 | C226: 123456789 | D226: 123456789

Sheet epu_idx
B1: UK | C1: US | D1: EA
A2: 1970q1 | B2: 71.60111 | C2: 123456789 | D2: 123456789
A3: 1970q2 | B3: 86.8982 | C3: 123456789 | D3: 123456789
A4: 1970q3 | B4: 71.28686 | C4: 123456789 | D4: 123456789
A5: 1970q4 | B5: 84.94344 | C5: 123456789 | D5: 123456789
A6: 1971q1 | B6: 87.18849 | C6: 123456789 | D6: 123456789
A7: 1971q2 | B7: 104.146 | C7: 123456789 | D7: 123456789
A8: 1971q3 | B8: 103.2461 | C8: 123456789 | D8: 123456789
A9: 1971q4 | B9: 113.4893 | C9: 123456789 | D9: 123456789
A10: 1972q1 | B10: 108.6299 | C10: 123456789 | D10: 123456789
A11: 1972q2 | B11: 101.6652 | C11: 123456789 | D11: 123456789
A12: 1972q3 | B12: 108.9231 | C12: 123456789 | D12: 123456789
A13: 1972q4 | B13: 100.5814 | C13: 123456789 | D13: 123456789
... A226: 2026q1 | B226: 307.40158 | C226: 123456789 | D226: 123456789

Sheet house_price_growth
B1: UK | C1: US | D1: EA
A2: 1970q1 | B2: 0.1497 | C2: 123456789 | D2: 123456789
A3: 1970q2 | B3: -3.1935 | C3: 123456789 | D3: 123456789
A4: 1970q3 | B4: 0.6825 | C4: 123456789 | D4: 123456789
A5: 1970q4 | B5: -2.3023 | C5: 123456789 | D5: 123456789
A6: 1971q1 | B6: -0.8242 | C6: 123456789 | D6: 123456789
A7: 1971q2 | B7: 0.7281 | C7: 123456789 | D7: 123456789
A8: 1971q3 | B8: 1.6004 | C8: 123456789 | D8: 123456789
A9: 1971q4 | B9: 7.2469 | C9: 123456789 | D9: 123456789
A10: 1972q1 | B10: 12.5296 | C10: 123456789 | D10: 123456789
A11: 1972q2 | B11: 22.093 | C11: 123456789 | D11: 123456789
A12: 1972q3 | B12: 30.8904 | C12: 123456789 | D12: 123456789
A13: 1972q4 | B13: 33.2083 | C13: 123456789 | D13: 123456789
... A226: 2026q1 | B226: -0.636 | C226: 123456789 | D226: 123456789

Sheet ln_housing_approvals
B1: UK | C1: US | D1: EA
A2: 1970q1 | B2: =LN(housing_approvals!B2) -> 12.266341 | C2: 123456789 | D2: 123456789
A3: 1970q2 | B3: =LN(housing_approvals!B3) -> 12.145177 | C3: 123456789 | D3: 123456789
A4: 1970q3 | B4: =LN(housing_approvals!B4) -> 12.284364 | C4: 123456789 | D4: 123456789
A5: 1970q4 | B5: =LN(housing_approvals!B5) -> 12.178938 | C5: 123456789 | D5: 123456789
A6: 1971q1 | B6: =LN(housing_approvals!B6) -> 12.232535 | C6: 123456789 | D6: 123456789
A7: 1971q2 | B7: =LN(housing_approvals!B7) -> 12.285891 | C7: 123456789 | D7: 123456789
A8: 1971q3 | B8: =LN(housing_approvals!B8) -> 12.31467 | C8: 123456789 | D8: 123456789
A9: 1971q4 | B9: =LN(housing_approvals!B9) -> 12.483261 | C9: 123456789 | D9: 123456789
A10: 1972q1 | B10: =LN(housing_approvals!B10) -> 12.618797 | C10: 123456789 | D10: 123456789
A11: 1972q2 | B11: =LN(housing_approvals!B11) -> 12.825373 | C11: 123456789 | D11: 123456789
A12: 1972q3 | B12: =LN(housing_approvals!B12) -> 12.983817 | C12: 123456789 | D12: 123456789
A13: 1972q4 | B13: =LN(housing_approvals!B13) -> 13.021698 | C13: 123456789 | D13: 123456789
... A225: 2025q4 | B225: =LN(housing_approvals!B225) -> 12.148375 | C225: 123456789 | D225: 123456789
A226: 2026q1 | B226: 12.14837 | C226: 123456789 | D226: 123456789

Sheet housing_approvals
B1: UK | C1: US | D1: EA
A2: 1970q1 | B2: =spliced_housing_approvals!D2 -> 212424.41 | C2: 123456789 | D2: 123456789
A3: 1970q2 | B3: =spliced_housing_approvals!D3 -> 188184.35 | C3: 123456789 | D3: 123456789
A4: 1970q3 | B4: =spliced_housing_approvals!D4 -> 216287.5 | C4: 123456789 | D4: 123456789
A5: 1970q4 | B5: =spliced_housing_approvals!D5 -> 194646.05 | C5: 123456789 | D5: 123456789
A6: 1971q1 | B6: =spliced_housing_approvals!D6 -> 205363.09 | C6: 123456789 | D6: 123456789
A7: 1971q2 | B7: =spliced_housing_approvals!D7 -> 216618.13 | C7: 123456789 | D7: 123456789
