Workbook

Sheet read_me
A3: ctry | B3: sheet name | C3: description | D3: source | E3: time span | F3: note
A4: UK | B4: g4Infl | C4: CPIH ANNUAL RATE 00: ALL ITEMS 2015=100 | D4: ONS | E4: 1989m1:2025m8 | F4: https://www.ons.gov.uk/economy/inflationandpriceindices/timeseries/l55o/mm23
A5: UK | B5: avg12Infl | C5: Average inflation in the last 12 months (including the current) | D5: own computations | E5: 1989m12:2025m8 | F5: -
A6: UK | B6: infl1_m | C6: CPI expectations in next calendar year | D6: Consensus Economics | E6: 1989m10:2025m9 | F6: spliced series from 2004m1 (sheet spliced_infl1_m)
A7: UK | B7: Oil | C7: Crude Oil Prices: Brent - Europe | D7: FRED | E7: 1987m6:2025m9
A8: UK | B8: g12oil | C8: Crude Oil Prices Inflation: Brent - Europe | D8: FRED | E8: 1988m6:2025m9 | F8: percentage change from a year ago (dollars per barrel) https://fred.stlouisfed.org/series/DCOILBRENTEU
A9: UK | B9: g12cpicore_global | C9: Consumer price indices (CPIs, HICPs), COICOP 1999 - All items non-food non-energy | D9: OECD | E9: 1971m1:2025m8 | F9: freq: M | reference: G7 | methodology: National | measure: CPI | Unit: % per annum | expenditure: all items non-food non-energy | adjustment: neither seasonal nor calendar adj |transformation: growth rate over 1 y https://data-explorer.oecd.org/vis?pg=0&bp=true&snb=16&df[ds]=dsDisseminateFinalDMZ&df[id]=DSD_PRICES%40DF_PRICES_ALL&df[ag]=OECD.SDD.TPS&df[vs]=&pd=%2C&dq=G7.M.N.CPI.PA._TXCP01_NRG.N.GY&to[TIME_PERIOD]=false&vw=tb&lc=en
A10: UK | B10: vu tightness | C10: Ratio of vacancy over unemployment (labour market tightness) | D10: a-millennium-of-macroeconomic-data-for-the-uk | E10: 1971m2:2025m6 | F10: sheet M5. Administrative unemp 1881+ (ratio between colomn AB (spliced vacancy) and colomn K (LFS unemployment). The data end in 2016. they have been complemented with the following data (check vu_extra_data sheet) https://www.ons.gov.uk/employmentandlabourmarket/peoplenotinwork/unemployment/datasets/vacanciesandunemploymentvacs01 Notice that each datapoint refers to the MIDDLE month in a 3 month period
A11: UK | B11: delta1vu tightness | C11: Delta 12m of vu tightness | D11: own computations | E11: 1972m2:2025m6
A12: UK | B12: bond_spread | C12: Corporate bond spread | D12: a-millennium-of-macroeconomic-data-for-the-uk + own computations + countercyclical capital buffer.xslsx (BOE) | E12: 1970m1:2025m9 | F12: series is available also for early period. We use colomn D of sheet 7. Global corp. bond spreads fron countercyclical capita buffer.xlsx from 1997 m1 onward and before we spliced colomn AJ sheet M11. Mthly corp bond yields from a millenium of macro data (see spliced_corporate_spread). countercyclical capita buffer.xlsx are at the daily level. We calculate monthly series as the average daily value withing a month. Computations are in Codes--> Intermediate_codes other_series.do (stata file)
A13: UK | B13: ue | C13: Unemployment rate (aged 16 and over, seasonally adjusted): % | D13: ONS | E13: 1971m2:2025m6 | F13: https://www.ons.gov.uk/employmentandlabourmarket/peoplenotinwork/unemployment/timeseries/mgsx/lms
A14: UK | B14: g4cpi | C14: CPI ANNUAL RATE 00: ALL ITEMS 2015=100 | D14: ONS | E14: 1989m1:2025m8 | F14: https://www.ons.gov.uk/economy/inflationandpriceindices/timeseries/d7g7/mm23
A15: UK | B15: avgcpi | C15: Average cpi inflation in the last 12 months (including the current) | D15: own computations | E15: 1989m12:2025m8
A16: UK | B16: g4cpinoener | C16: CPI 12mth: Excluding energy (SP) 2015=100 | D16: ONS | E16: 1989m1:2025m8 | F16: https://www.ons.gov.uk/economy/inflationandpriceindices/timeseries/dko7/mm23
A17: UK | B17: avgcpinoener | C17: Average cpi inflation Excluding energy in the last 12 months (including the current) | D17: own computations | E17: 1989m12:2025m8
A18: UK | B18: import_deflator | C18: Total Trade (TT): WW: Imports: BOP: IDEF: SA | D18: ONS | E18: 1970m1:2025m7 | F18: For the period after 1997m1 we use the monthly data from https://www.ons.gov.uk/economy/nationalaccounts/balanceofpayments/timeseries/ctwk/mret (Giulia is cross-checking with stat department.). For the period pre 1997m1 we linearly interpolate the quarterly data from the following series: Imports of goods and services deflator:SA (https://www.ons.gov.uk/economy/grossdomesticproductgdp/timeseries/ybfz/ukea) Interpolation of the series is performed in stata (other_series,do). Note: we assign the quarterly value to the last quarter in the month. Aggregation of the monthly interpolated series and the monthly series is performed here in the sheet (import_defl_qm)
A19: UK | B19: yoy_growth_import_deflator | C19: y-o-y growth in import deflator | D19: own computations | E19: 1971m1:2025m7
A20: UK | B20: import_defl_FAME | C20: import deflator | D20: BOE (FAME) | E20: 1970m1:2025m7 | F20: from deflator_longerTS.xlsx Giulia's email 20/08 So the cool thing about what Carleton is proposing is that we can get a deflator from 1955, by dividing prices and volumes and interpolating which are quarterly and interpolating them to monthly. So we don’t have to estimate anything: This obtains the deflator by dividing imports in current prices (CP) over imports in volumes (CVM) Total Trade (TT): WW: Imports: BOP: CP: SA Total Trade (TT): WW: Imports: BOP: CVM: SA Deflator = CP/CVM Post-1997: we have monthly data Pre-1997, we have quarterly so do a fancy interpolation to get implied monthly estimates
A21: UK | B21: yoy_growth_import_defl_FAME | C21: y-o-y growth in import deflator FAME | D21: own computations | E21: 1971m1:2025m7
A22: UK | B22: vu_tight_hp_filter | C22: level of v/u tightness minus HP filtered level of v/u tightnes (one-side) | D22: this dataset + own calculations | E22: 1988m1:2025m3 | F22: available inside the folder intermediate_code "other_series_monthly.m | L22: series is available also for early period. We use colomn D of sheet 7. Global corp. bond spreads fron countercyclical capita buffer.xlsx from 1997 m1 onward and before we spliced colomn AJ sheet M11. Mthly corp bond yields from a millenium of macro data (see spliced_corporate_spread). countercyclical capita buffer.xlsx are at the daily level. We calculate monthly series as the average daily value withing a month. Computations are in Codes--> Intermediate_codes other_series.do (stata file)
A23: UK | B23: ugap_kalman_filter | C23: Unemployment gap (using unemployment rate derived with KF as natural rate of unemployemnt) | D23: own computations | E23: 1989m4:2025m3 | F23: available inside the folder intermediate_code "other_series_monthly.m
A24: UK | B24: ugap_hp_filter | C24: unemployment minus HP filtered unemployment (one-side) | D24: this dataset + own calculations | E24: 1988m1:2025m3 | F24: available inside the folder intermediate_code "other_series_monthly.m

Sheet FAME Persistence2
A1: 19 | B1: bond_spread
A2: Fame Links | B2: $A$5 | C2: A1:A685 | D2: famedate | E2: 46114.513 | F2: TRUE | G2: famedate | H2: 1970 | I2: 2026 | J2: 0 | K2: m | L2: FALSE | M2: TRUE | N2: FALSE
A3: Fame Links | B3: $I$5 | C3: A1:A8090 | D3: famedate | E3: 46114.513 | F3: TRUE | G3: famedate | H3: 1996 | I3: 2026 | J3: 0 | K3: b | L3: FALSE | M3: TRUE | N3: FALSE
A4: Fame Links | B4: $C$6 | C4: A1:A684 | E4: 46114.513 | F4: TRUE | G4: D7G7.m | H4: 1970 | I4: 2026 | J4: 0 | K4: m | L4: FALSE | M4: FALSE | N4: FALSE
A5: Fame Links | B5: $D$6 | C5: A1:A684 | E5: 46114.513 | F5: TRUE | G5: UKCCPHM1.M | H5: 1970 | I5: 2026 | J5: 0 | K5: m | L5: FALSE | M5: FALSE | N5: FALSE
A6: Fame Links | B6: $E$6 | C6: A1:A684 | E6: 46114.513 | F6: TRUE | G6: UKCCPHM2.M | H6: 1970 | I6: 2026 | J6: 0 | K6: m | L6: FALSE | M6: FALSE | N6: FALSE
A7: Fame Links | B7: $F$6 | C7: A1:A684 | E7: 46114.513 | F7: TRUE | G7: ap2y.m[t-1] | H7: 1970 | I7: 2026 | J7: 0 | K7: m | L7: FALSE | M7: FALSE | N7: FALSE
A8: Fame Links | B8: $G$6 | C8: A1:A684 | E8: 46114.513 | F8: TRUE | G8: mgsc_dp.m[t-1] | H8: 1970 | I8: 2026 | J8: 0 | K8: m | L8: FALSE | M8: FALSE | N8: FALSE
A9: Fame Links | B9: $J$6 | C9: A1:A8089 | E9: 46114.513 | F9: TRUE | G9: UR00_OAS.b | H9: 1996 | I9: 2026 | J9: 0 | K9: b | L9: FALSE | M9: FALSE | N9: FALSE
A10: Sheet2 | B10: $A$5 | C10: A1:A445 | D10: famedate | E10: 46114.508 | F10: TRUE | G10: famedate | H10: 1990 | I10: 2026 | J10: 0 | K10: m | L10: FALSE | M10: TRUE | N10: FALSE
A11: Sheet2 | B11: $B$5 | C11: A1:A445 | D11: bqat.m/bpic.m | E11: 46114.508 | F11: TRUE | G11: bqat.m/bpic.m | H11: 1990 | I11: 2026 | J11: 0 | K11: m | L11: FALSE | M11: TRUE | N11: FALSE
A12: Sheet2 | B12: $C$5 | C12: A1:A445 | D12: ikbi.m-bqat.m | E12: 46114.508 | F12: TRUE | G12: ikbi.m-bqat.m | H12: 1990 | I12: 2026 | J12: 0 | K12: m | L12: FALSE | M12: TRUE | N12: FALSE
A13: Sheet2 | B13: $D$5 | C13: A1:A445 | D13: ikbl.m-bpic.m | E13: 46114.508 | F13: TRUE | G13: ikbl.m-bpic.m | H13: 1990 | I13: 2026 | J13: 0 | K13: m | L13: FALSE | M13: TRUE | N13: FALSE
A14: Sheet2 | B14: $F$5 | C14: A1:A445 | D14: conv2ma(gsalspt.b/uss.b) | E14: 46114.508 | F14: TRUE | G14: conv2ma(gsalspt.b/uss.b) | H14: 1990 | I14: 2026 | J14: 0 | K14: m | L14: FALSE | M14: TRUE | N14: FALSE
A15: Imp_def_fameGM | B15: $A$5 | C15: A1:A685 | D15: famedate | E15: 46114.51 | F15: TRUE | G15: famedate | H15: 1970 | I15: 2026 | J15: 0 | K15: m | L15: FALSE | M15: TRUE | N15: FALSE
A16: Imp_def_fameGM | B16: $B$5 | C16: A1:A685 | D16: overlay(ikbi.m/ikbl.m*100,convgen(ikbi.q/ikbl.q*100,monthly,averaged,linear,yes)) | E16: 46114.51 | F16: TRUE | G16: overlay(ikbi.m/ikbl.m*100,convgen(ikbi.q/ikbl.q*100,monthly,averaged,linear,yes)) | H16: 1970 | I16: 2026 | J16: 0 | K16: m | L16: FALSE | M16: TRUE | N16: FALSE
A17: import_defl_FAME | B17: $B$5 | D17: #N/A | E17: 0
A18: import_defl_FAME | B18: $A$5 | D18: #N/A | E18: 0
A19: Sheet1 | B19: $A$5 | D19: #N/A | E19: 0 | F19: TRUE | G19: 1970m3 | I19: 1970m1 | J19: 0 | K19: 1970m2 | L19: FALSE | M19: TRUE | N19: FALSE
A20: Sheet1 | B20: $B$5 | D20: #N/A | E20: 0 | F20: TRUE | G20: overlay(ikbi.m/ikbl.m*100,convgen(ikbi.q/ikbl.q*100,monthly,averaged,linear,yes)) | I20: 1970m1 | J20: 0 | K20: 1970m2 | L20: FALSE | M20: TRUE | N20: FALSE

Sheet Fame Links
A1: 1970 | B1: 1970m1 | I1: 1996
A2: 2026 | B2: 2026m1 | I2: 2026 | M2: Note | N2: the latest ONS release is as Jun-Sep, and so on FAME its saved as the August number, but we treat it as September as it has september data. its unemployment in the 3 months to september and the t-1 is just to adjust for this
A3: m | B3: m | I3: b
A4: famedate | B4: 25599 | C4: CPI | D4: Consensus | E4: Consensus | F4: Vacancies | G4: Unemployment | I4: famedate
A5: =[1]!FAMEData($A$4, $A$1, $A$2, 0,$A$3,"Down","Heading","Normal") -> famedate | B5: 25627 | C5: D7G7.m | D5: UKCCPHM1.M | E5: UKCCPHM2.M | F5: ap2y.m[t-1] | G5: mgsc_dp.m[t-1] | I5: =[1]!FAMEData($I$4, $I$1, $I$2, 0,$I$3,"Down","Heading","Normal") -> famedate | J5: UR00_OAS.b
A6: 25599 | B6: 25658 | C6: =[1]!FAMEData($C$5, $A$1,$A$2, 0,$A$3, "Down", "No Heading", "Normal") | D6: =[1]!FAMEData(D5, $A$1, $A$2, 0, $A$3, "Down", "No Heading", "Normal") | E6: =[1]!FAMEData(E5, $A$1, $A$2, 0, $A$3, "Down", "No Heading", "Normal") | F6: =[1]!FAMEData(F5, $A$1, $A$2, 0, $A$3, "Down", "No Heading", "Normal") | G6: =[1]!FAMEData(G5, $A$1, $A$2, 0, $A$3, "Down", "No Heading", "Normal") | I6: 35065 | J6: =[1]!FAMEData(J5, $I$1, $I$2, 0, $I$3, "Down", "No Heading", "Normal")
A7: 25627 | B7: 25688 | I7: 35066
A8: 25658 | B8: 25719 | I8: 35067
A9: 25688 | B9: 25749 | I9: 35068
A10: 25719 | B10: 25780 | I10: 35069
A11: 25749 | B11: 25811 | I11: 35072
A12: 25780 | B12: 25841 | I12: 35073
A13: 25811 | B13: 25872 | I13: 35074
A14: 25841 | B14: 25902 | I14: 35075
A15: 25872 | B15: 25933 | I15: 35076
A16: 25902 | B16: 25964 | I16: 35079
A17: 25933 | B17: 25992 | I17: 35080
A18: 25964 | B18: 26023 | I18: 35081
A19: 25992 | B19: 26053 | I19: 35082
A20: 26023 | B20: 26084 | G20: 980 | I20: 35083
A21: 26053 | B21: 26114 | G21: 998 | I21: 35086
A22: 26084 | B22: 26145 | G22: 1023 | I22: 35087
A23: 26114 | B23: 26176 | G23: 1045 | I23: 35088
A24: 26145 | B24: 26206 | G24: 1062 | I24: 35089
A25: 26176 | B25: 26237 | G25: 1068 | I25: 35090
A26: 26206 | B26: 26267 | G26: 1076 | I26: 35093
A27: 26237 | B27: 26298 | G27: 1090 | I27: 35094
A28: 26267 | B28: 26329 | G28: 1113 | I28: 35095
A29: 26298 | B29: 26358 | G29: 1133 | I29: 35096
A30: 26329 | B30: 26389 | G30: 1143 | I30: 35097
A31: 26358 | B31: 26419 | G31: 1149 | I31: 35100
... A233: 32508 | B233: 32567 | G233: 2293 | I233: 35382
A234: 32539 | B234: 32598 | C234: 4.9 | G234: 2253 | I234: 35383
A235: 32567 | B235: 32628 | C235: 5 | G235: 2213 | I235: 35384
A236: 32598 | B236: 32659 | C236: 5 | G236: 2179 | I236: 35387
A237: 32628 | B237: 32689 | C237: 5.3 | G237: 2140 | I237: 35388
A238: 32659 | B238: 32720 | C238: 5.3 | G238: 2106 | I238: 35389
A239: 32689 | B239: 32751 | C239: 5.2 | G239: 2083 | I239: 35390
A240: 32720 | B240: 32781 | C240: 5.2 | G240: 2071 | I240: 35391
A241: 32751 | B241: 32812 | C241: 5 | G241: 2057 | I241: 35394
...

Sheet Sheet2
A1: 1990
A2: 2026
A3: m
A4: famedate | B4: bqat.m/bpic.m | C4: ikbi.m-bqat.m | D4: ikbl.m-bpic.m | F4: conv2ma(gsalspt.b/uss.b)
A5: =[1]!FAMEData($A$4, $A$1, $A$2, 0,$A$3,"Down","Heading","Normal") -> famedate | B5: =[1]!FAMEData($B$4, $A$1, $A$2, 0,$A$3,"Down","Heading","Normal") -> bqat.m/bpic.m | C5: =[1]!FAMEData($C$4, $A$1, $A$2, 0,$A$3,"Down","Heading","Normal") -> ikbi.m-bqat.m | D5: =[1]!FAMEData($D$4, $A$1, $A$2, 0,$A$3,"Down","Heading","Normal") -> ikbl.m-bpic.m | F5: =[1]!FAMEData($F$4, $A$1, $A$2, 0,$A$3,"Down","Heading","Normal") -> conv2ma(gsalspt.b/uss.b)
A6: 32904 | B6: 0.3080855 | E6: =C6/D6 -> #DIV/0! | F6: 123.64496
A7: 32932 | B7: 0.30942133 | E7: =C7/D7 -> #DIV/0! | F7: 119.3997
A8: 32963 | B8: 0.30205415 | E8: =C8/D8 -> #DIV/0! | F8: 127.37489
A9: 32993 | B9: 0.28089888 | E9: =C9/D9 -> #DIV/0! | F9: 129.43937
A10: 33024 | B10: 0.27317956 | E10: =C10/D10 -> #DIV/0! | F10: 127.65673
A11: 33054 | B11: 0.27295163 | E11: =C11/D11 -> #DIV/0! | F11: 121.3704
A12: 33085 | B12: 0.26933702 | E12: =C12/D12 -> #DIV/0! | F12: 110.44262
A13: 33116 | B13: 0.28571429 | E13: =C13/D13 -> #DIV/0! | F13: 100.53098
A14: 33146 | B14: 0.32931354 | E14: =C14/D14 -> #DIV/0! | F14: 100.45201
A15: 33177 | B15: 0.37881508 | E15: =C15/D15 -> #DIV/0! | F15: 96.276237
A16: 33207 | B16: 0.3639407 | E16: =C16/D16 -> #DIV/0! | F16: 94.085349
A17: 33238 | B17: 0.34917556 | E17: =C17/D17 -> #DIV/0! | F17: 95.657377
... A29: 33603 | B29: 0.26077098 | E29: =C29/D29 -> #DIV/0! | F29: 102.33339
A30: 33634 | B30: 0.25940594 | C30: 11375 | E30: =C30/D30 -> #DIV/0! | F30: 105.30599
A31: 33663 | B31: 0.25418363 | C31: 11864 | E31: =C31/D31 -> #DIV/0! | F31: 109.16726
A32: 33694 | B32: 0.2641604 | C32: 11665 | E32: =C32/D32 -> #DIV/0! | F32: 111.15181
A33: 33724 | B33: 0.26225279 | C33: 12101 | E33: =C33/D33 -> #DIV/0! | F33: 107.74131
A34: 33755 | B34: 0.27118644 | C34: 12126 | E34: =C34/D34 -> #DIV/0! | F34: 103.28261
A35: 33785 | B35: 0.28658824 | C35: 11827 | E35: =C35/D35 -> #DIV/0! | F35: 100.86595
A36: 33816 | B36: 0.28594771 | C36: 11870 | E36: =C36/D36 -> #DIV/0! | F36: 93.476428
A37: 33847 | B37: 0.27167113 | C37: 12003 | E37: =C37/D37 -> #DIV/0! | F37: 89.514852
A38: 33877 | B38: 0.26490669 | C38: 11751 | E38: =C38/D38 -> #DIV/0! | F38: 95.148045
A39: 33908 | B39: 0.27842004 | C39: 12463 | E39: =C39/D39 -> #DIV/0! | F39: 107.01414
A40: 33938 | B40: 0.2839784 | C40: 12787 | E40: =C40/D40 -> #DIV/0! | F40: 118.81568
A41: 33969 | B41: 0.29509853 | C41: 13222 | E41: =C41/D41 -> #DIV/0! | F41: 117.76362
... A77: 35064 | B77: 0.30763984 | C77: 17491 | E77: =C77/D77 -> #DIV/0! | F77: 147.77629
A78: 35095 | B78: 0.31988636 | E78: =C78/D78 -> #DIV/0! | F78: 147.46285
A79: 35124 | B79: 0.31629756 | E79: =C79/D79 -> #DIV/0! | F79: 149.17095
A80: 35155 | B80: 0.33391204 | E80: =C80/D80 -> #DIV/0! | F80: 151.11239
A81: 35185 | B81: 0.34642857 | E81: =C81/D81 -> #DIV/0! | F81: 162.36849
A82: 35216 | B82: 0.32520776 | E82: =C82/D82 -> #DIV/0! | F82: 167.37782
A83: 35246 | B83: 0.3126935 | E83: =C83/D83 -> #DIV/0! | F83: 152.40667
A84: 35277 | B84: 0.32397408 | E84: =C84/D84 -> #DIV/0! | F84: 147.56072
A85: 35308 | B85: 0.33178923 | E85: =C85/D85 -> #DIV/0! | F85: 145.96132
A86: 35338 | B86: 0.35290664 | E86: =C86/D86 -> #DIV/0! | F86: 141.1382
...

Sheet g4Infl
B1: UK | C1: US | D1: EA
A2: 1970m1 | B2: 123456789 | C2: 123456789 | D2: 123456789
A3: 1970m2 | B3: 123456789 | C3: 123456789 | D3: 123456789
A4: 1970m3 | B4: 123456789 | C4: 123456789 | D4: 123456789
A5: 1970m4 | B5: 123456789 | C5: 123456789 | D5: 123456789
A6: 1970m5 | B6: 123456789 | C6: 123456789 | D6: 123456789
A7: 1970m6 | B7: 123456789 | C7: 123456789 | D7: 123456789
A8: 1970m7 | B8: 123456789 | C8: 123456789 | D8: 123456789
A9: 1970m8 | B9: 123456789 | C9: 123456789 | D9: 123456789
A10: 1970m9 | B10: 123456789 | C10: 123456789 | D10: 123456789
A11: 1970m10 | B11: 123456789 | C11: 123456789 | D11: 123456789
A12: 1970m11 | B12: 123456789 | C12: 123456789 | D12: 123456789
A13: 1970m12 | B13: 123456789 | C13: 123456789 | D13: 123456789
... A617: 2021m4 | B617: 1.6 | C617: 123456789 | D617: 123456789
A618: 2021m5 | B618: 2.1 | C618: 123456789 | D618: 123456789 | R618: =428-92 -> 336
A619: 2021m6 | B619: 2.4 | C619: 123456789 | D619: 123456789
A620: 2021m7 | B620: 2.1 | C620: 123456789 | D620: 123456789
A621: 2021m8 | B621: 3 | C621: 123456789 | D621: 123456789
A622: 2021m9 | B622: 2.9 | C622: 123456789 | D622: 123456789
A623: 2021m10 | B623: 3.8 | C623: 123456789 | D623: 123456789
A624: 2021m11 | B624: 4.6 | C624: 123456789 | D624: 123456789
A625: 2021m12 | B625: 4.8 | C625: 123456789 | D625: 123456789
A626: 2022m1 | B626: 4.9 | C626: 123456789 | D626: 123456789
A627: 2022m2 | B627: 5.5 | C627: 123456789 | D627: 123456789
A628: 2022m3 | B628: 6.2 | C628: 123456789 | D628: 123456789
A629: 2022m4 | B629: 7.8 | C629: 123456789 | D629: 123456789
A630: 2022m5 | B630: 7.9 | C630: 123456789 | D630: 123456789
... A654: 2024m5 | B654: 2.8 | C654: 123456789 | D654: 123456789
A655: 2024m6 | B655: 2.8 | C655: 123456789 | D655: 123456789 | R655: 4+R61828-92
A656: 2024m7 | B656: 3.1 | C656: 123456789 | D656: 123456789
A657: 2024m8 | B657: 3.1 | C657: 123456789 | D657: 123456789
A658: 2024m9 | B658: 2.6 | C658: 123456789 | D658: 123456789 | P658: 92
A659: 2024m10 | B659: 3.2 | C659: 123456789 | D659: 123456789
A660: 2024m11 | B660: 3.5 | C660: 123456789 | D660: 123456789
A661: 2024m12 | B661: 3.5 | C661: 123456789 | D661: 123456789
A662: 2025m1 | B662: 3.9 | C662: 123456789 | D662: 123456789
A663: 2025m2 | B663: 3.7 | C663: 123456789 | D663: 123456789
A664: 2025m3 | B664: 3.4 | C664: 123456789 | D664: 123456789
A665: 2025m4 | B665: 4.1 | C665: 123456789 | D665: 123456789
A666: 2025m5 | B666: 4 | C666: 123456789 | D666: 123456789
...

Sheet g4cpi
B1: UK | C1: US | D1: EA
A2: 1970m1 | B2: 123456789 | C2: 123456789 | D2: 123456789
A3: 1970m2 | B3: 123456789 | C3: 123456789 | D3: 123456789
A4: 1970m3 | B4: 123456789 | C4: 123456789 | D4: 123456789
A5: 1970m4 | B5: 123456789 | C5: 123456789 | D5: 123456789
A6: 1970m5 | B6: 123456789 | C6: 123456789 | D6: 123456789
A7: 1970m6 | B7: 123456789 | C7: 123456789 | D7: 123456789
A8: 1970m7 | B8: 123456789 | C8: 123456789 | D8: 123456789
A9: 1970m8 | B9: 123456789 | C9: 123456789 | D9: 123456789
A10: 1970m9 | B10: 123456789 | C10: 123456789 | D10: 123456789
A11: 1970m10 | B11: 123456789 | C11: 123456789 | D11: 123456789
A12: 1970m11 | B12: 123456789 | C12: 123456789 | D12: 123456789
A13: 1970m12 | B13: 123456789 | C13: 123456789 | D13: 123456789
... A229: 1988m12 | B229: 123456789 | C229: 123456789 | D229: 123456789
A230: 1989m1 | B230: ='Fame Links'!C234 -> 4.9 | C230: 123456789 | D230: 123456789
A231: 1989m2 | B231: ='Fame Links'!C235 -> 5 | C231: 123456789 | D231: 123456789
A232: 1989m3 | B232: ='Fame Links'!C236 -> 5 | C232: 123456789 | D232: 123456789
A233: 1989m4 | B233: ='Fame Links'!C237 -> 5.3 | C233: 123456789 | D233: 123456789
A234: 1989m5 | B234: ='Fame Links'!C238 -> 5.3 | C234: 123456789 | D234: 123456789
A235: 1989m6 | B235: ='Fame Links'!C239 -> 5.2 | C235: 123456789 | D235: 123456789
A236: 1989m7 | B236: ='Fame Links'!C240 -> 5.2 | C236: 123456789 | D236: 123456789
A237: 1989m8 | B237: ='Fame Links'!C241 -> 5 | C237: 123456789 | D237: 123456789
A238: 1989m9 | B238: ='Fame Links'!C242 -> 5.2 | C238: 123456789 | D238: 123456789
A239: 1989m10 | B239: ='Fame Links'!C243 -> 5.5 | C239: 123456789 | D239: 123456789
A240: 1989m11 | B240: ='Fame Links'!C244 -> 5.5 | C240: 123456789 | D240: 123456789
A241: 1989m12 | B241: ='Fame Links'!C245 -> 5.5 | C241: 123456789 | D241: 123456789
... A670: 2025m9 | B670: ='Fame Links'!C674 -> 3.8 | C670: 123456789 | D670: 123456789
A671: 2025m10 | B671: 3.6 | C671: 123456789 | D671: 123456789
A672: 2025m11 | B672: 3.2 | C672: 123456789 | D672: 123456789
A673: 2025m12 | B673: 3.4 | C673: 123456789 | D673: 123456789
A674: 2026m1 | B674: 3 | C674: 123456789 | D674: 123456789
A675: 2026m2 | B675: 3 | C675: 123456789 | D675: 123456789

Sheet avgcpi
B1: UK | C1: US | D1: EA
A2: 1970m1 | B2: 123456789 | C2: 123456789 | D2: 123456789
A3: 1970m2 | B3: 123456789 | C3: 123456789 | D3: 123456789
A4: 1970m3 | B4: 123456789 | C4: 123456789 | D4: 123456789
A5: 1970m4 | B5: 123456789 | C5: 123456789 | D5: 123456789
A6: 1970m5 | B6: 123456789 | C6: 123456789 | D6: 123456789
A7: 1970m6 | B7: 123456789 | C7: 123456789 | D7: 123456789
A8: 1970m7 | B8: 123456789 | C8: 123456789 | D8: 123456789
A9: 1970m8 | B9: 123456789 | C9: 123456789 | D9: 123456789
A10: 1970m9 | B10: 123456789 | C10: 123456789 | D10: 123456789
A11: 1970m10 | B11: 123456789 | C11: 123456789 | D11: 123456789
A12: 1970m11 | B12: 123456789 | C12: 123456789 | D12: 123456789
A13: 1970m12 | B13: 123456789 | C13: 123456789 | D13: 123456789
... A240: 1989m11 | B240: 123456789 | C240: 123456789 | D240: 123456789
A241: 1989m12 | B241: =AVERAGE(g4cpi!B230:B241) -> 5.2166667 | C241: 123456789 | D241: 123456789
A242: 1990m1 | B242: =AVERAGE(g4cpi!B231:B242) -> 5.2833333 | C242: 123456789 | D242: 123456789
A243: 1990m2 | B243: =AVERAGE(g4cpi!B232:B243) -> 5.3583333 | C243: 123456789 | D243: 123456789
A244: 1990m3 | B244: =AVERAGE(g4cpi!B233:B244) -> 5.4416667 | C244: 123456789 | D244: 123456789
A245: 1990m4 | B245: =AVERAGE(g4cpi!B234:B245) -> 5.5333333 | C245: 123456789 | D245: 123456789
A246: 1990m5 | B246: =AVERAGE(g4cpi!B235:B246) -> 5.6583333 | C246: 123456789 | D246: 123456789
A247: 1990m6 | B247: =AVERAGE(g4cpi!B236:B247) -> 5.8 | C247: 123456789 | D247: 123456789
A248: 1990m7 | B248: =AVERAGE(g4cpi!B237:B248) -> 5.9333333 | C248: 123456789 | D248: 123456789
A249: 1990m8 | B249: =AVERAGE(g4cpi!B238:B249) -> 6.1583333 | C249: 123456789 | D249: 123456789
A250: 1990m9 | B250: =AVERAGE(g4cpi!B239:B250) -> 6.4 | C250: 123456789 | D250: 123456789
A251: 1990m10 | B251: =AVERAGE(g4cpi!B240:B251) -> 6.6166667 | C251: 123456789 | D251: 123456789
A252: 1990m11 | B252: =AVERAGE(g4cpi!B241:B252) -> 6.8083333 | C252: 123456789 | D252: 123456789
... A675: 2026m2 | B675: =AVERAGE(g4cpi!B664:B675) -> 3.3916667 | C675: 123456789 | D675: 123456789

Sheet infl1_m
B1: UK | C1: US | D1: EA
A2: 1970m1 | B2: 123456789 | C2: 123456789 | D2: 123456789
A3: 1970m2 | B3: 123456789 | C3: 123456789 | D3: 123456789
A4: 1970m3 | B4: 123456789 | C4: 123456789 | D4: 123456789
A5: 1970m4 | B5: 123456789 | C5: 123456789 | D5: 123456789
A6: 1970m5 | B6: 123456789 | C6: 123456789 | D6: 123456789
A7: 1970m6 | B7: 123456789 | C7: 123456789 | D7: 123456789
A8: 1970m7 | B8: 123456789 | C8: 123456789 | D8: 123456789
A9: 1970m8 | B9: 123456789 | C9: 123456789 | D9: 123456789
A10: 1970m9 | B10: 123456789 | C10: 123456789 | D10: 123456789
A11: 1970m10 | B11: 123456789 | C11: 123456789 | D11: 123456789
A12: 1970m11 | B12: 123456789 | C12: 123456789 | D12: 123456789
A13: 1970m12 | B13: 123456789 | C13: 123456789 | D13: 123456789
... A238: 1989m9 | B238: 123456789 | C238: 123456789 | D238: 123456789
A239: 1989m10 | B239: =spliced_infl1_m!E59 -> 4.3294451 | C239: 123456789 | D239: 123456789
A240: 1989m11 | B240: =spliced_infl1_m!E60 -> 4.4584389 | C240: 123456789 | D240: 123456789
A241: 1989m12 | B241: =spliced_infl1_m!E61 -> 4.6860313 | C241: 123456789 | D241: 123456789
A242: 1990m1 | B242: =spliced_infl1_m!E62 -> 4.7445974 | C242: 123456789 | D242: 123456789
A243: 1990m2 | B243: =spliced_infl1_m!E63 -> 3.6970793 | C243: 123456789 | D243: 123456789
A244: 1990m3 | B244: =spliced_infl1_m!E64 -> 3.9083621 | C244: 123456789 | D244: 123456789
A245: 1990m4 | B245: =spliced_infl1_m!E65 -> 4.0536654 | C245: 123456789 | D245: 123456789
A246: 1990m5 | B246: =spliced_infl1_m!E66 -> 4.1537468 | C246: 123456789 | D246: 123456789
A247: 1990m6 | B247: =spliced_infl1_m!E67 -> 4.223433 | C247: 123456789 | D247: 123456789
A248: 1990m7 | B248: =spliced_infl1_m!E68 -> 4.266431 | C248: 123456789 | D248: 123456789
A249: 1990m8 | B249: =spliced_infl1_m!E69 -> 4.2975674 | C249: 123456789 | D249: 123456789
A250: 1990m9 | B250: =spliced_infl1_m!E70 -> 4.661567 | C250: 123456789 | D250: 123456789
... A675: 2026m2 | B675: =spliced_infl1_m!E495 -> 2.225 | C675: 123456789 | D675: 123456789

Sheet delta1vu_tightness
B1: UK | C1: US | D1: EA
A2: 1970m1 | B2: 123456789 | C2: 123456789 | D2: 123456789
A3: 1970m2 | B3: 123456789 | C3: 123456789 | D3: 123456789
A4: 1970m3 | B4: 123456789 | C4: 123456789 | D4: 123456789
A5: 1970m4 | B5: 123456789 | C5: 123456789 | D5: 123456789
A6: 1970m5 | B6: 123456789 | C6: 123456789 | D6: 123456789
A7: 1970m6 | B7: 123456789 | C7: 123456789 | D7: 123456789
A8: 1970m7 | B8: 123456789 | C8: 123456789 | D8: 123456789
A9: 1970m8 | B9: 123456789 | C9: 123456789 | D9: 123456789
A10: 1970m9 | B10: 123456789 | C10: 123456789 | D10: 123456789
A11: 1970m10 | B11: 123456789 | C11: 123456789 | D11: 123456789
A12: 1970m11 | B12: 123456789 | C12: 123456789 | D12: 123456789
A13: 1970m12 | B13: 123456789 | C13: 123456789 | D13: 123456789
... A26: 1972m1 | B26: 123456789 | C26: 123456789 | D26: 123456789
A27: 1972m2 | B27: =vu_tightness!B27-vu_tightness!B15 -> -0.071985261 | C27: 123456789 | D27: 123456789
A28: 1972m3 | B28: =vu_tightness!B28-vu_tightness!B16 -> -0.043455634 | C28: 123456789 | D28: 123456789
A29: 1972m4 | B29: =vu_tightness!B29-vu_tightness!B17 -> -0.020486241 | C29: 123456789 | D29: 123456789
A30: 1972m5 | B30: =vu_tightness!B30-vu_tightness!B18 -> -0.0079784041 | C30: 123456789 | D30: 123456789
A31: 1972m6 | B31: =vu_tightness!B31-vu_tightness!B19 -> 0.0081541111 | C31: 123456789 | D31: 123456789
A32: 1972m7 | B32: =vu_tightness!B32-vu_tightness!B20 -> 0.02529586 | C32: 123456789 | D32: 123456789
A33: 1972m8 | B33: =vu_tightness!B33-vu_tightness!B21 -> 0.036417347 | C33: 123456789 | D33: 123456789
A34: 1972m9 | B34: =vu_tightness!B34-vu_tightness!B22 -> 0.047723138 | C34: 123456789 | D34: 123456789
A35: 1972m10 | B35: =vu_tightness!B35-vu_tightness!B23 -> 0.070341593 | C35: 123456789 | D35: 123456789
A36: 1972m11 | B36: =vu_tightness!B36-vu_tightness!B24 -> 0.096198225 | C36: 123456789 | D36: 123456789
A37: 1972m12 | B37: =vu_tightness!B37-vu_tightness!B25 -> 0.12423284 | C37: 123456789 | D37: 123456789
A38: 1973m1 | B38: =vu_tightness!B38-vu_tightness!B26 -> 0.14984419 | C38: 123456789 | D38: 123456789
... A674: 2026m1 | B674: =vu_tightness!B674-vu_tightness!B662 -> -0.12634607 | C674: 123456789 | D674: 123456789
A675: 2026m2 | B675: -0.12635 | C675: 123456789 | D675: 123456789

Sheet yoy_growth_import_deflator
B1: UK | C1: US | D1: EA
A2: 1970m1 | B2: 123456789 | C2: 123456789 | D2: 123456789
A3: 1970m2 | B3: 123456789 | C3: 123456789 | D3: 123456789
A4: 1970m3 | B4: 123456789 | C4: 123456789 | D4: 123456789
A5: 1970m4 | B5: 123456789 | C5: 123456789 | D5: 123456789
A6: 1970m5 | B6: 123456789 | C6: 123456789 | D6: 123456789
A7: 1970m6 | B7: 123456789 | C7: 123456789 | D7: 123456789
A8: 1970m7 | B8: 123456789 | C8: 123456789 | D8: 123456789
A9: 1970m8 | B9: 123456789 | C9: 123456789 | D9: 123456789
A10: 1970m9 | B10: 123456789 | C10: 123456789 | D10: 123456789
A11: 1970m10 | B11: 123456789 | C11: 123456789 | D11: 123456789
A12: 1970m11 | B12: 123456789 | C12: 123456789 | D12: 123456789
A13: 1970m12 | B13: 123456789 | C13: 123456789 | D13: 123456789
A14: 1971m1 | B14: =(Imp_def_fameGM!B18/Imp_def_fameGM!B6-1)*100 -> 4.6254237 | C14: 123456789 | D14: 123456789
A15: 1971m2 | B15: =(Imp_def_fameGM!B19/Imp_def_fameGM!B7-1)*100 -> 3.9026299 | C15: 123456789 | D15: 123456789
A16: 1971m3 | B16: =(Imp_def_fameGM!B20/Imp_def_fameGM!B8-1)*100 -> 4.3720623 | C16: 123456789 | D16: 123456789
A17: 1971m4 | B17: =(Imp_def_fameGM!B21/Imp_def_fameGM!B9-1)*100 -> 5.0481738 | C17: 123456789 | D17: 123456789
A18: 1971m5 | B18: =(Imp_def_fameGM!B22/Imp_def_fameGM!B10-1)*100 -> 5.5957605 | C18: 123456789 | D18: 123456789
A19: 1971m6 | B19: =(Imp_def_fameGM!B23/Imp_def_fameGM!B11-1)*100 -> 5.3866288 | C19: 123456789 | D19: 123456789
A20: 1971m7 | B20: =(Imp_def_fameGM!B24/Imp_def_fameGM!B12-1)*100 -> 5.0509502 | C20: 123456789 | D20: 123456789
A21: 1971m8 | B21: =(Imp_def_fameGM!B25/Imp_def_fameGM!B13-1)*100 -> 4.6739215 | C21: 123456789 | D21: 123456789
A22: 1971m9 | B22: =(Imp_def_fameGM!B26/Imp_def_fameGM!B14-1)*100 -> 4.0949646 | C22: 123456789 | D22: 123456789
A23: 1971m10 | B23: =(Imp_def_fameGM!B27/Imp_def_fameGM!B15-1)*100 -> 3.4878843 | C23: 123456789 | D23: 123456789
A24: 1971m11 | B24: =(Imp_def_fameGM!B28/Imp_def_fameGM!B16-1)*100 -> 2.9306073 | C24: 123456789 | D24: 123456789
A25: 1971m12 | B25: =(Imp_def_fameGM!B29/Imp_def_fameGM!B17-1)*100 -> 2.6485282 | C25: 123456789 | D25: 123456789
... A674: 2026m1 | B674: =(Imp_def_fameGM!B678/Imp_def_fameGM!B666-1)*100 -> -0.87387559 | C674: 123456789 | D674: 123456789
A675: 2026m2 | B675: -0.873876 | C675: 123456789 | D675: 123456789

Sheet bond_spread
B1: UK | C1: US | D1: EA
A2: 1970m1 | B2: =spliced_corporate_spread!E2 -> 150 | C2: 123456789 | D2: 123456789
A3: 1970m2 | B3: =spliced_corporate_spread!E3 -> 145 | C3: 123456789 | D3: 123456789
A4: 1970m3 | B4: =spliced_corporate_spread!E4 -> 123 | C4: 123456789 | D4: 123456789
A5: 1970m4 | B5: =spliced_corporate_spread!E5 -> 123 | C5: 123456789 | D5: 123456789
A6: 1970m5 | B6: =spliced_corporate_spread!E6 -> 132 | C6: 123456789 | D6: 123456789
A7: 1970m6 | B7: =spliced_corporate_spread!E7 -> 134 | C7: 123456789 | D7: 123456789
A8: 1970m7 | B8: =spliced_corporate_spread!E8 -> 148 | C8: 123456789 | D8: 123456789
A9: 1970m8 | B9: =spliced_corporate_spread!E9 -> 122 | C9: 123456789 | D9: 123456789
A10: 1970m9 | B10: =spliced_corporate_spread!E10 -> 120 | C10: 123456789 | D10: 123456789
A11: 1970m10 | B11: =spliced_corporate_spread!E11 -> 112 | C11: 123456789 | D11: 123456789
A12: 1970m11 | B12: =spliced_corporate_spread!E12 -> 105 | C12: 123456789 | D12: 123456789
A13: 1970m12 | B13: =spliced_corporate_spread!E13 -> 120 | C13: 123456789 | D13: 123456789
... A675: 2026m2 | B675: =spliced_corporate_spread!E675 -> 81.4 | C675: 123456789 | D675: 123456789

Sheet vu_tightness
B1: UK | C1: US | D1: EA
A2: 1970m1 | B2: 123456789 | C2: 123456789 | D2: 123456789
A3: 1970m2 | B3: 123456789 | C3: 123456789 | D3: 123456789
A4: 1970m3 | B4: 123456789 | C4: 123456789 | D4: 123456789
A5: 1970m4 | B5: 123456789 | C5: 123456789 | D5: 123456789
A6: 1970m5 | B6: 123456789 | C6: 123456789 | D6: 123456789
A7: 1970m6 | B7: 123456789 | C7: 123456789 | D7: 123456789
A8: 1970m7 | B8: 123456789 | C8: 123456789 | D8: 123456789
A9: 1970m8 | B9: 123456789 | C9: 123456789 | D9: 123456789
A10: 1970m9 | B10: 123456789 | C10: 123456789 | D10: 123456789
A11: 1970m10 | B11: 123456789 | C11: 123456789 | D11: 123456789
A12: 1970m11 | B12: 123456789 | C12: 123456789 | D12: 123456789
A13: 1970m12 | B13: 123456789 | C13: 123456789 | D13: 123456789
... A378: 2001m5 | B378: 0.4763018 | C378: 123456789 | D378: 123456789
A379: 2001m6 | B379: =vu_extra_data!F368 -> 0.46331396 | C379: 123456789 | D379: 123456789
A380: 2001m7 | B380: =vu_extra_data!F369 -> 0.45785729 | C380: 123456789 | D380: 123456789
A381: 2001m8 | B381: =vu_extra_data!F370 -> 0.44714714 | C381: 123456789 | D381: 123456789
A382: 2001m9 | B382: =vu_extra_data!F371 -> 0.44575909 | C382: 123456789 | D382: 123456789
A383: 2001m10 | B383: =vu_extra_data!F372 -> 0.42958476 | C383: 123456789 | D383: 123456789
A384: 2001m11 | B384: =vu_extra_data!F373 -> 0.41865416 | C384: 123456789 | D384: 123456789
A385: 2001m12 | B385: =vu_extra_data!F374 -> 0.39548691 | C385: 123456789 | D385: 123456789
A386: 2002m1 | B386: =vu_extra_data!F375 -> 0.3991624 | C386: 123456789 | D386: 123456789
A387: 2002m2 | B387: =vu_extra_data!F376 -> 0.40858435 | C387: 123456789 | D387: 123456789
A388: 2002m3 | B388: =vu_extra_data!F377 -> 0.40855682 | C388: 123456789 | D388: 123456789
A389: 2002m4 | B389: =vu_extra_data!F378 -> 0.4066126 | C389: 123456789 | D389: 123456789
A390: 2002m5 | B390: =vu_extra_data!F379 -> 0.39745369 | C390: 123456789 | D390: 123456789
... A674: 2026m1 | B674: =vu_extra_data!F663 -> 0.3906426 | C674: 123456789 | D674: 123456789

Sheet vu_extra_data
B1: LFS unempl old | C1: ONS_vacancy_old | D1: ONS_vacancy_new | E1: LFS unempl new | F1: v/u
G2: ap2y.m[t-1] | H2: mgsc_dp.m[t-1]
A3: 1971m1
A4: 1971m2 | B4: 980
A5: 1971m3 | B5: 998
A6: 1971m4 | B6: 1023
A7: 1971m5 | B7: 1045
A8: 1971m6 | B8: 1062
A9: 1971m7 | B9: 1068
A10: 1971m8 | B10: 1076
A11: 1971m9 | B11: 1090
A12: 1971m10 | B12: 1113
A13: 1971m11 | B13: 1133
A14: 1971m12 | B14: 1143
A15: 1972m1 | B15: 1149
... A366: 2001m4 | B366: 1431
A367: 2001m5 | B367: 1468 | C367: 680 | D367: ='Fame Links'!F382 -> 0 | E367: ='Fame Links'!G382 -> 1430.5672 | F367: =D367/E367 -> 0
A368: 2001m6 | B368: 1472 | C368: 673 | D368: ='Fame Links'!F383 -> 680 | E368: ='Fame Links'!G383 -> 1467.6873 | F368: =D368/E368 -> 0.46331396
A369: 2001m7 | B369: 1483 | C369: 661 | D369: ='Fame Links'!F384 -> 674 | E369: ='Fame Links'!G384 -> 1472.0744 | F369: =D369/E369 -> 0.45785729
A370: 2001m8 | B370: 1487 | C370: 661 | D370: ='Fame Links'!F385 -> 663 | E370: ='Fame Links'!G385 -> 1482.7334 | F370: =D370/E370 -> 0.44714714
A371: 2001m9 | B371: 1487 | C371: 637 | D371: ='Fame Links'!F386 -> 663 | E371: ='Fame Links'!G386 -> 1487.3505 | F371: =D371/E371 -> 0.44575909
A372: 2001m10 | B372: 1495 | C372: 625 | D372: ='Fame Links'!F387 -> 639 | E372: ='Fame Links'!G387 -> 1487.483 | F372: =D372/E372 -> 0.42958476
A373: 2001m11 | B373: 1520 | C373: 602 | D373: ='Fame Links'!F388 -> 626 | E373: ='Fame Links'!G388 -> 1495.2676 | F373: =D373/E373 -> 0.41865416
A374: 2001m12 | B374: 1518 | C374: 607 | D374: ='Fame Links'!F389 -> 601 | E374: ='Fame Links'!G389 -> 1519.6458 | F374: =D374/E374 -> 0.39548691
A375: 2002m1 | B375: 1508 | C375: 616 | D375: ='Fame Links'!F390 -> 606 | E375: ='Fame Links'!G390 -> 1518.1791 | F375: =D375/E375 -> 0.3991624
A376: 2002m2 | B376: 1515 | C376: 619 | D376: ='Fame Links'!F391 -> 616 | E376: ='Fame Links'!G391 -> 1507.6446 | F376: =D376/E376 -> 0.40858435
A377: 2002m3 | B377: 1522 | C377: 619 | D377: ='Fame Links'!F392 -> 619 | E377: ='Fame Links'!G392 -> 1515.0891 | F377: =D377/E377 -> 0.40855682
A378: 2002m4 | B378: 1542 | C378: 612 | D378: ='Fame Links'!F393 -> 619 | E378: ='Fame Links'!G393 -> 1522.3335 | F378: =D378/E378 -> 0.4066126
... A555: 2017m1 | B555: 1559 | C555: 761 | D555: ='Fame Links'!F570 -> 748 | E555: ='Fame Links'!G570 -> 1575.3416 | F555: =D555/E555 -> 0.47481766
A556: 2017m2 | C556: 770 | D556: ='Fame Links'!F571 -> 764 | E556: ='Fame Links'!G571 -> 1552.7917 | F556: =D556/E556 -> 0.49201706
A557: 2017m3 | C557: 784 | D557: ='Fame Links'!F572 -> 771 | E557: ='Fame Links'!G572 -> 1530.0311 | F557: =D557/E557 -> 0.50391133
A558: 2017m4 | C558: 781 | D558: ='Fame Links'!F573 -> 791 | E558: ='Fame Links'!G573 -> 1522.609 | F558: =D558/E558 -> 0.51950303
A559: 2017m5 | C559: 780 | D559: ='Fame Links'!F574 -> 786 | E559: ='Fame Links'!G574 -> 1492.0005 | F559: =D559/E559 -> 0.52680947
A560: 2017m6 | C560: 774 | D560: ='Fame Links'!F575 -> 786 | E560: ='Fame Links'!G575 -> 1487.7081 | F560: =D560/E560 -> 0.52832945
A561: 2017m7 | C561: 781 | D561: ='Fame Links'!F576 -> 784 | E561: ='Fame Links'!G576 -> 1460.2758 | F561: =D561/E561 -> 0.53688487
A562: 2017m8 | C562: 786 | D562: ='Fame Links'!F577 -> 793 | E562: ='Fame Links'!G577 -> 1455.6207 | F562: =D562/E562 -> 0.54478478
A563: 2017m9 | C563: 780 | D563: ='Fame Links'!F578 -> 800 | E563: ='Fame Links'!G578 -> 1432.4556 | F563: =D563/E563 -> 0.55848152
A564: 2017m10 | D564: ='Fame Links'!F579 -> 812 | E564: ='Fame Links'!G579 -> 1425.7463 | F564: =D564/E564 -> 0.56952629
A565: 2017m11 | D565: ='Fame Links'!F580 -> 819 | E565: ='Fame Links'!G580 -> 1441.2187 | F565: =D565/E565 -> 0.56826906
A566: 2017m12 | D566: ='Fame Links'!F581 -> 820 | E566: ='Fame Links'!G581 -> 1466.9411 | F566: =D566/E566 -> 0.55898631
...

Sheet spliced_infl1_m
A1: FAMEDATE | B1: old_infl1_m | C1: growrh_old_inf | D1: new_infl1_m | E1: infl1_m_spliced | G1: note: new_inf1_m from simon email 13/06/2025 at 16:56
A2: 31078
A3: 31106
A4: 31137
A5: 31167
A6: 31198
A7: 31228
A8: 31259
A9: 31290
A10: 31320
A11: 31351
A12: 31381
A13: 31412
... A58: 32781
A59: 32812 | B59: 5.84 | E59: =E60/(1+C60) -> 4.3294451
A60: 32842 | B60: 6.014 | C60: =B60/B59-1 -> 0.029794521 | E60: =E61/(1+C61) -> 4.4584389
A61: 32873 | B61: 6.321 | C61: =B61/B60-1 -> 0.051047556 | E61: =E62/(1+C62) -> 4.6860313
A62: 32904 | B62: 6.4 | C62: =B62/B61-1 -> 0.012498022 | E62: =E63/(1+C63) -> 4.7445974
A63: 32932 | B63: 4.987 | C63: =B63/B62-1 -> -0.22078125 | E63: =E64/(1+C64) -> 3.6970793
A64: 32963 | B64: 5.272 | C64: =B64/B63-1 -> 0.057148586 | E64: =E65/(1+C65) -> 3.9083621
A65: 32993 | B65: 5.468 | C65: =B65/B64-1 -> 0.037177542 | E65: =E66/(1+C66) -> 4.0536654
A66: 33024 | B66: 5.603 | C66: =B66/B65-1 -> 0.0246891 | E66: =E67/(1+C67) -> 4.1537468
A67: 33054 | B67: 5.697 | C67: =B67/B66-1 -> 0.016776727 | E67: =E68/(1+C68) -> 4.223433
A68: 33085 | B68: 5.755 | C68: =B68/B67-1 -> 0.010180797 | E68: =E69/(1+C69) -> 4.266431
A69: 33116 | B69: 5.797 | C69: =B69/B68-1 -> 0.0072980017 | E69: =E70/(1+C70) -> 4.2975674
A70: 33146 | B70: 6.288 | C70: =B70/B69-1 -> 0.084698982 | E70: =E71/(1+C71) -> 4.661567
A71: 33177 | B71: 6.683 | C71: =B71/B70-1 -> 0.062818066 | E71: =E72/(1+C72) -> 4.9543976
... A229: 37986 | B229: 2.483 | C229: =B229/B228-1 -> 0.00080612656 | E229: =E230/(1+C230) -> 1.8407555
A230: 38017 | B230: 2.397 | C230: =B230/B229-1 -> -0.034635522 | D230: ='Fame Links'!E414 -> 1.777 | E230: =D230 -> 1.777
A231: 38046 | B231: 2.366 | C231: =B231/B230-1 -> -0.012932833 | D231: ='Fame Links'!E415 -> 1.767 | E231: =D231 -> 1.767
A232: 38077 | B232: 2.389 | C232: =B232/B231-1 -> 0.0097210482 | D232: ='Fame Links'!E416 -> 1.738 | E232: =D232 -> 1.738
A233: 38107 | B233: 2.368 | C233: =B233/B232-1 -> -0.0087902888 | D233: ='Fame Links'!E417 -> 1.753 | E233: =D233 -> 1.753
A234: 38138 | B234: 2.432 | C234: =B234/B233-1 -> 0.027027027 | D234: ='Fame Links'!E418 -> 1.768 | E234: =D234 -> 1.768
A235: 38168 | B235: 2.444 | C235: =B235/B234-1 -> 0.0049342105 | D235: ='Fame Links'!E419 -> 1.78 | E235: =D235 -> 1.78
A236: 38199 | B236: 2.443 | C236: =B236/B235-1 -> -0.0004091653 | D236: ='Fame Links'!E420 -> 1.796 | E236: =D236 -> 1.796
A237: 38230 | B237: 2.427 | C237: =B237/B236-1 -> -0.0065493246 | D237: ='Fame Links'!E421 -> 1.78 | E237: =D237 -> 1.78
A238: 38260 | B238: 2.41 | C238: =B238/B237-1 -> -0.0070045323 | D238: ='Fame Links'!E422 -> 1.834 | E238: =D238 -> 1.834
A239: 38291 | B239: 2.408 | C239: =B239/B238-1 -> -0.00082987552 | D239: ='Fame Links'!E423 -> 1.768 | E239: =D239 -> 1.768
A240: 38321 | B240: 2.326 | C240: =B240/B239-1 -> -0.034053156 | D240: ='Fame Links'!E424 -> 1.677 | E240: =D240 -> 1.677
A241: 38352 | B241: 2.313 | C241: =B241/B240-1 -> -0.005588994 | D241: ='Fame Links'!E425 -> 1.672 | E241: =D241 -> 1.672
...

Sheet Imp_def_fameGM
A1: 1970
A2: 2026
A3: m
A4: famedate | B4: overlay(ikbi.m/ikbl.m*100,convgen(ikbi.q/ikbl.q*100,monthly,averaged,linear,yes))
A5: =[1]!FAMEData($A$4, $A$1, $A$2, 0,$A$3,"Down","Heading","Normal") -> famedate | B5: =[1]!FAMEData(B4, $A$1, $A$2, 0,$A$3,"Down","Heading","Normal") -> overlay(ikbi.m/ikbl.m*100,convgen(ikbi.q/ikbl.q*100,monthly,averaged,linear,yes)) | L5: quarterly_series_interpolated | M5: monthly_series | N5: final_series
A6: 25599 | B6: 9.7098762 | K6: 25569 | L6: 9.9 | N6: =L6 -> 9.9
A7: 25627 | B7: 9.8195451 | K7: 25600 | L7: 10 | N7: =L7 -> 10
A8: 25658 | B8: 9.8310413 | K8: 25628 | L8: 10.1 | N8: =L8 -> 10.1
A9: 25688 | B9: 9.8271383 | K9: 25659 | L9: 10.133333 | N9: =L9 -> 10.133333
A10: 25719 | B10: 9.8284068 | K10: 25689 | L10: 10.166667 | N10: =L10 -> 10.166667
A11: 25749 | B11: 9.8600376 | K11: 25720 | L11: 10.2 | N11: =L11 -> 10.2
A12: 25780 | B12: 9.8968401 | K12: 25750 | L12: 10.233333 | N12: =L12 -> 10.233333
A13: 25811 | B13: 9.9354913 | K13: 25781 | L13: 10.266667 | N13: =L13 -> 10.266667
A14: 25841 | B14: 9.9803989 | K14: 25812 | L14: 10.3 | N14: =L14 -> 10.3
A15: 25872 | B15: 10.026401 | K15: 25842 | L15: 10.333333 | N15: =L15 -> 10.333333
A16: 25902 | B16: 10.072028 | K16: 25873 | L16: 10.366667 | N16: =L16 -> 10.366667
A17: 25933 | B17: 10.115349 | K17: 25903 | L17: 10.4 | N17: =L17 -> 10.4
... A329: 35430 | B329: 66.616568 | K329: 35400 | L329: 69.5 | N329: =L329 -> 69.5
A330: 35461 | B330: 65.150055 | K330: 35431 | L330: 68.733333 | M330: =B330 -> 65.150055 | N330: =M330 -> 65.150055
A331: 35489 | B331: 64.890167 | K331: 35462 | L331: 67.966667 | M331: =B331 -> 64.890167 | N331: =M331 -> 64.890167
A332: 35520 | B332: 64.567133 | K332: 35490 | L332: 67.2 | M332: =B332 -> 64.567133 | N332: =M332 -> 64.567133
A333: 35550 | B333: 64.478045 | K333: 35521 | L333: 66.733333 | M333: =B333 -> 64.478045 | N333: =M333 -> 64.478045
A334: 35581 | B334: 63.999103 | K334: 35551 | L334: 66.266667 | M334: =B334 -> 63.999103 | N334: =M334 -> 63.999103
A335: 35611 | B335: 63.18303 | K335: 35582 | L335: 65.8 | M335: =B335 -> 63.18303 | N335: =M335 -> 63.18303
A336: 35642 | B336: 63.634943 | K336: 35612 | L336: 65.666667 | M336: =B336 -> 63.634943 | N336: =M336 -> 63.634943
A337: 35673 | B337: 63.10623 | K337: 35643 | L337: 65.533333 | M337: =B337 -> 63.10623 | N337: =M337 -> 63.10623
A338: 35703 | B338: 63.34046 | K338: 35674 | L338: 65.4 | M338: =B338 -> 63.34046 | N338: =M338 -> 63.34046
A339: 35734 | B339: 63.617535 | K339: 35704 | L339: 65.366667 | M339: =B339 -> 63.617535 | N339: =M339 -> 63.617535
A340: 35764 | B340: 62.925864 | K340: 35735 | L340: 65.333333 | M340: =B340 -> 62.925864 | N340: =M340 -> 62.925864
A341: 35795 | B341: 62.967797 | K341: 35765 | L341: 65.3 | M341: =B341 -> 62.967797 | N341: =M341 -> 62.967797
... A668: 45747 | B668: 99.387565 | K668: 45717 | L668: 101.6 | M668: =B668 -> 99.387565 | N668: =M668 -> 99.387565
A669: 45777 | B669: 99.569105 | K669: 45748 | M669: =B669 -> 99.569105 | N669: =M669 -> 99.569105
A670: 45808 | B670: 98.90699 | K670: 45778 | M670: =B670 -> 98.90699 | N670: =M670 -> 98.90699
A671: 45838 | B671: 99.261722 | K671: 45809 | M671: =B671 -> 99.261722 | N671: =M671 -> 99.261722
A672: 45869 | B672: 99.26283 | K672: 45839 | M672: =B672 -> 99.26283 | N672: =M672 -> 99.26283
A673: 45900 | B673: 98.03154 | K673: 45870 | M673: =B673 -> 98.03154 | N673: =M673 -> 98.03154
A674: 45930 | B674: 98.735175 | K674: 45901 | M674: =B674 -> 98.735175 | N674: =M674 -> 98.735175
A675: 45961 | B675: 100.60753 | K675: 45931 | M675: =B675 -> 100.60753 | N675: =M675 -> 100.60753
A676: 45991 | B676: 101.36143 | K676: 45962 | M676: =B676 -> 101.36143 | N676: =M676 -> 101.36143
A677: 46022 | B677: 100.12932 | K677: 45992 | M677: =B677 -> 100.12932 | N677: =M677 -> 100.12932
...

Sheet avg12Infl
B1: UK | C1: US | D1: EA
A2: 1970m1 | B2: 123456789 | C2: 123456789 | D2: 123456789
A3: 1970m2 | B3: 123456789 | C3: 123456789 | D3: 123456789
A4: 1970m3 | B4: 123456789 | C4: 123456789 | D4: 123456789
A5: 1970m4 | B5: 123456789 | C5: 123456789 | D5: 123456789
A6: 1970m5 | B6: 123456789 | C6: 123456789 | D6: 123456789
A7: 1970m6 | B7: 123456789 | C7: 123456789 | D7: 123456789
A8: 1970m7 | B8: 123456789 | C8: 123456789 | D8: 123456789
A9: 1970m8 | B9: 123456789 | C9: 123456789 | D9: 123456789
A10: 1970m9 | B10: 123456789 | C10: 123456789 | D10: 123456789
A11: 1970m10 | B11: 123456789 | C11: 123456789 | D11: 123456789
A12: 1970m11 | B12: 123456789 | C12: 123456789 | D12: 123456789
A13: 1970m12 | B13: 123456789 | C13: 123456789 | D13: 123456789
... A240: 1989m11 | B240: 123456789 | C240: 123456789 | D240: 123456789
A241: 1989m12 | B241: =AVERAGE(g4Infl!B230:B241) -> 5.7416667 | C241: 123456789 | D241: 123456789
A242: 1990m1 | B242: =AVERAGE(g4Infl!B231:B242) -> 5.7583333 | C242: 123456789 | D242: 123456789
A243: 1990m2 | B243: =AVERAGE(g4Infl!B232:B243) -> 5.8 | C243: 123456789 | D243: 123456789
A244: 1990m3 | B244: =AVERAGE(g4Infl!B233:B244) -> 5.825 | C244: 123456789 | D244: 123456789
A245: 1990m4 | B245: =AVERAGE(g4Infl!B234:B245) -> 6 | C245: 123456789 | D245: 123456789
A246: 1990m5 | B246: =AVERAGE(g4Infl!B235:B246) -> 6.1916667 | C246: 123456789 | D246: 123456789
A247: 1990m6 | B247: =AVERAGE(g4Infl!B236:B247) -> 6.3916667 | C247: 123456789 | D247: 123456789
A248: 1990m7 | B248: =AVERAGE(g4Infl!B237:B248) -> 6.6 | C248: 123456789 | D248: 123456789
A249: 1990m8 | B249: =AVERAGE(g4Infl!B238:B249) -> 6.8833333 | C249: 123456789 | D249: 123456789
A250: 1990m9 | B250: =AVERAGE(g4Infl!B239:B250) -> 7.175 | C250: 123456789 | D250: 123456789
A251: 1990m10 | B251: =AVERAGE(g4Infl!B240:B251) -> 7.4583333 | C251: 123456789 | D251: 123456789
A252: 1990m11 | B252: =AVERAGE(g4Infl!B241:B252) -> 7.75 | C252: 123456789 | D252: 123456789
... A670: 2025m9 | B670: =AVERAGE(g4Infl!B659:B670) -> 3.8166667 | C670: 123456789 | D670: 123456789

Sheet Oil
B1: UK | C1: US | D1: EA
A2: 1970m1 | B2: 123456789 | C2: 123456789 | D2: 123456789
A3: 1970m2 | B3: 123456789 | C3: 123456789 | D3: 123456789
A4: 1970m3 | B4: 123456789 | C4: 123456789 | D4: 123456789
A5: 1970m4 | B5: 123456789 | C5: 123456789 | D5: 123456789
A6: 1970m5 | B6: 123456789 | C6: 123456789 | D6: 123456789
A7: 1970m6 | B7: 123456789 | C7: 123456789 | D7: 123456789
A8: 1970m7 | B8: 123456789 | C8: 123456789 | D8: 123456789
A9: 1970m8 | B9: 123456789 | C9: 123456789 | D9: 123456789
A10: 1970m9 | B10: 123456789 | C10: 123456789 | D10: 123456789
A11: 1970m10 | B11: 123456789 | C11: 123456789 | D11: 123456789
A12: 1970m11 | B12: 123456789 | C12: 123456789 | D12: 123456789
A13: 1970m12 | B13: 123456789 | C13: 123456789 | D13: 123456789
... A673: 2025m12 | B673: 62.54 | C673: 123456789 | D673: 123456789

Sheet g4oil
B1: UK | C1: US | D1: EA
A2: 1970m1 | B2: 123456789 | C2: 123456789 | D2: 123456789
A3: 1970m2 | B3: 123456789 | C3: 123456789 | D3: 123456789
A4: 1970m3 | B4: 123456789 | C4: 123456789 | D4: 123456789
A5: 1970m4 | B5: 123456789 | C5: 123456789 | D5: 123456789
A6: 1970m5 | B6: 123456789 | C6: 123456789 | D6: 123456789
A7: 1970m6 | B7: 123456789 | C7: 123456789 | D7: 123456789
A8: 1970m7 | B8: 123456789 | C8: 123456789 | D8: 123456789
A9: 1970m8 | B9: 123456789 | C9: 123456789 | D9: 123456789
A10: 1970m9 | B10: 123456789 | C10: 123456789 | D10: 123456789
A11: 1970m10 | B11: 123456789 | C11: 123456789 | D11: 123456789
A12: 1970m11 | B12: 123456789 | C12: 123456789 | D12: 123456789
A13: 1970m12 | B13: 123456789 | C13: 123456789 | D13: 123456789
... A675: 2026m2 | B675: -6.03277 | C675: 123456789 | D675: 123456789

Sheet g4cpicore_global
B1: UK | C1: US | D1: EA
A2: 1970m1 | B2: 123456789 | C2: 123456789 | D2: 123456789
A3: 1970m2 | B3: 123456789 | C3: 123456789 | D3: 123456789
A4: 1970m3 | B4: 123456789 | C4: 123456789 | D4: 123456789
A5: 1970m4 | B5: 123456789 | C5: 123456789 | D5: 123456789
A6: 1970m5 | B6: 123456789 | C6: 123456789 | D6: 123456789
A7: 1970m6 | B7: 123456789 | C7: 123456789 | D7: 123456789
A8: 1970m7 | B8: 123456789 | C8: 123456789 | D8: 123456789
A9: 1970m8 | B9: 123456789 | C9: 123456789 | D9: 123456789
A10: 1970m9 | B10: 123456789 | C10: 123456789 | D10: 123456789
A11: 1970m10 | B11: 123456789 | C11: 123456789 | D11: 123456789
A12: 1970m11 | B12: 123456789 | C12: 123456789 | D12: 123456789
A13: 1970m12 | B13: 123456789 | C13: 123456789 | D13: 123456789
... A670: 2025m9 | B670: 2.98 | C670: 123456789 | D670: 123456789

Sheet ue
B1: UK | C1: US | D1: EA
A2: 1970m1 | B2: 123456789 | C2: 123456789 | D2: 123456789
A3: 1970m2 | B3: 123456789 | C3: 123456789 | D3: 123456789
A4: 1970m3 | B4: 123456789 | C4: 123456789 | D4: 123456789
A5: 1970m4 | B5: 123456789 | C5: 123456789 | D5: 123456789
A6: 1970m5 | B6: 123456789 | C6: 123456789 | D6: 123456789
A7: 1970m6 | B7: 123456789 | C7: 123456789 | D7: 123456789
A8: 1970m7 | B8: 123456789 | C8: 123456789 | D8: 123456789
A9: 1970m8 | B9: 123456789 | C9: 123456789 | D9: 123456789
A10: 1970m9 | B10: 123456789 | C10: 123456789 | D10: 123456789
A11: 1970m10 | B11: 123456789 | C11: 123456789 | D11: 123456789
A12: 1970m11 | B12: 123456789 | C12: 123456789 | D12: 123456789
A13: 1970m12 | B13: 123456789 | C13: 123456789 | D13: 123456789
... A675: 2026m2 | B675: 5 | C675: 123456789 | D675: 123456789

Sheet g4cpinoener
B1: UK | C1: US | D1: EA
A2: 1970m1 | B2: 123456789 | C2: 123456789 | D2: 123456789
A3: 1970m2 | B3: 123456789 | C3: 123456789 | D3: 123456789
A4: 1970m3 | B4: 123456789 | C4: 123456789 | D4: 123456789
A5: 1970m4 | B5: 123456789 | C5: 123456789 | D5: 123456789
A6: 1970m5 | B6: 123456789 | C6: 123456789 | D6: 123456789
A7: 1970m6 | B7: 123456789 | C7: 123456789 | D7: 123456789
A8: 1970m7 | B8: 123456789 | C8: 123456789 | D8: 123456789
A9: 1970m8 | B9: 123456789 | C9: 123456789 | D9: 123456789
A10: 1970m9 | B10: 123456789 | C10: 123456789 | D10: 123456789
A11: 1970m10 | B11: 123456789 | C11: 123456789 | D11: 123456789
A12: 1970m11 | B12: 123456789 | C12: 123456789 | D12: 123456789
A13: 1970m12 | B13: 123456789 | C13: 123456789 | D13: 123456789
... A670: 2025m9 | B670: 3.9 | C670: 123456789 | D670: 123456789

Sheet avgcpinoener
B1: UK | C1: US | D1: EA
A2: 1970m1 | B2: 123456789 | C2: 123456789 | D2: 123456789
A3: 1970m2 | B3: 123456789 | C3: 123456789 | D3: 123456789
A4: 1970m3 | B4: 123456789 | C4: 123456789 | D4: 123456789
A5: 1970m4 | B5: 123456789 | C5: 123456789 | D5: 123456789
A6: 1970m5 | B6: 123456789 | C6: 123456789 | D6: 123456789
A7: 1970m6 | B7: 123456789 | C7: 123456789 | D7: 123456789
A8: 1970m7 | B8: 123456789 | C8: 123456789 | D8: 123456789
A9: 1970m8 | B9: 123456789 | C9: 123456789 | D9: 123456789
A10: 1970m9 | B10: 123456789 | C10: 123456789 | D10: 123456789
A11: 1970m10 | B11: 123456789 | C11: 123456789 | D11: 123456789
A12: 1970m11 | B12: 123456789 | C12: 123456789 | D12: 123456789
A13: 1970m12 | B13: 123456789 | C13: 123456789 | D13: 123456789
... A240: 1989m11 | B240: 123456789 | C240: 123456789 | D240: 123456789
A241: 1989m12 | B241: =AVERAGE(g4cpinoener!B230:B241) -> 5.0833333 | C241: 123456789 | D241: 123456789
A242: 1990m1 | B242: =AVERAGE(g4cpinoener!B231:B242) -> 5.125 | C242: 123456789 | D242: 123456789
A243: 1990m2 | B243: =AVERAGE(g4cpinoener!B232:B243) -> 5.2 | C243: 123456789 | D243: 123456789
A244: 1990m3 | B244: =AVERAGE(g4cpinoener!B233:B244) -> 5.2916667 | C244: 123456789 | D244: 123456789
A245: 1990m4 | B245: =AVERAGE(g4cpinoener!B234:B245) -> 5.4083333 | C245: 123456789 | D245: 123456789
A246: 1990m5 | B246: =AVERAGE(g4cpinoener!B235:B246) -> 5.5666667 | C246: 123456789 | D246: 123456789
A247: 1990m6 | B247: =AVERAGE(g4cpinoener!B236:B247) -> 5.725 | C247: 123456789 | D247: 123456789
A248: 1990m7 | B248: =AVERAGE(g4cpinoener!B237:B248) -> 5.8833333 | C248: 123456789 | D248: 123456789
A249: 1990m8 | B249: =AVERAGE(g4cpinoener!B238:B249) -> 6.0833333 | C249: 123456789 | D249: 123456789
A250: 1990m9 | B250: =AVERAGE(g4cpinoener!B239:B250) -> 6.275 | C250: 123456789 | D250: 123456789
A251: 1990m10 | B251: =AVERAGE(g4cpinoener!B240:B251) -> 6.425 | C251: 123456789 | D251: 123456789
A252: 1990m11 | B252: =AVERAGE(g4cpinoener!B241:B252) -> 6.575 | C252: 123456789 | D252: 123456789
... A670: 2025m9 | B670: =AVERAGE(g4cpinoener!B659:B670) -> 3.65 | C670: 123456789 | D670: 123456789

Sheet import_deflator
B1: UK | C1: US | D1: EA
A2: 1970m1 | B2: =import_defl_qm!D2 -> 9.9 | C2: 123456789 | D2: 123456789
A3: 1970m2 | B3: =import_defl_qm!D3 -> 10 | C3: 123456789 | D3: 123456789
A4: 1970m3 | B4: =import_defl_qm!D4 -> 10.1 | C4: 123456789 | D4: 123456789
A5: 1970m4 | B5: =import_defl_qm!D5 -> 10.133333 | C5: 123456789 | D5: 123456789
A6: 1970m5 | B6: =import_defl_qm!D6 -> 10.166667 | C6: 123456789 | D6: 123456789
A7: 1970m6 | B7: =import_defl_qm!D7 -> 10.2 | C7: 123456789 | D7: 123456789
A8: 1970m7 | B8: =import_defl_qm!D8 -> 10.233333 | C8: 123456789 | D8: 123456789
A9: 1970m8 | B9: =import_defl_qm!D9 -> 10.266667 | C9: 123456789 | D9: 123456789
A10: 1970m9 | B10: =import_defl_qm!D10 -> 10.3 | C10: 123456789 | D10: 123456789
A11: 1970m10 | B11: =import_defl_qm!D11 -> 10.333333 | C11: 123456789 | D11: 123456789
A12: 1970m11 | B12: =import_defl_qm!D12 -> 10.366667 | C12: 123456789 | D12: 123456789
A13: 1970m12 | B13: =import_defl_qm!D13 -> 10.4 | C13: 123456789 | D13: 123456789
... A325: 1996m12 | B325: =import_defl_qm!D325 -> 69.5 | C325: 123456789 | D325: 123456789
A326: 1997m1 | B326: 65.1 | C326: 123456789 | D326: 123456789
A327: 1997m2 | B327: 64.9 | C327: 123456789 | D327: 123456789
A328: 1997m3 | B328: 64.6 | C328: 123456789 | D328: 123456789
A329: 1997m4 | B329: 64.5 | C329: 123456789 | D329: 123456789
A330: 1997m5 | B330: 64 | C330: 123456789 | D330: 123456789
A331: 1997m6 | B331: 63.2 | C331: 123456789 | D331: 123456789
A332: 1997m7 | B332: 63.6 | C332: 123456789 | D332: 123456789
A333: 1997m8 | B333: 63.1 | C333: 123456789 | D333: 123456789
A334: 1997m9 | B334: 63.4 | C334: 123456789 | D334: 123456789
A335: 1997m10 | B335: 63.6 | C335: 123456789 | D335: 123456789
A336: 1997m11 | B336: 62.9 | C336: 123456789 | D336: 123456789
A337: 1997m12 | B337: 63 | C337: 123456789 | D337: 123456789
... A670: 2025m9 | B670: 98.2 | C670: 123456789 | D670: 123456789

Sheet import_defl_FAME
B1: UK | C1: US | D1: EA
A2: 1970m1 | B2: 9.7098762 | C2: 123456789 | D2: 123456789
A3: 1970m2 | B3: 9.8195451 | C3: 123456789 | D3: 123456789
A4: 1970m3 | B4: 9.8310413 | C4: 123456789 | D4: 123456789
A5: 1970m4 | B5: 9.8271383 | C5: 123456789 | D5: 123456789
A6: 1970m5 | B6: 9.8284068 | C6: 123456789 | D6: 123456789
A7: 1970m6 | B7: 9.8600376 | C7: 123456789 | D7: 123456789
A8: 1970m7 | B8: 9.8968401 | C8: 123456789 | D8: 123456789
A9: 1970m8 | B9: 9.9354913 | C9: 123456789 | D9: 123456789
A10: 1970m9 | B10: 9.9803989 | C10: 123456789 | D10: 123456789
A11: 1970m10 | B11: 10.026401 | C11: 123456789 | D11: 123456789
A12: 1970m11 | B12: 10.072028 | C12: 123456789 | D12: 123456789
A13: 1970m12 | B13: 10.115349 | C13: 123456789 | D13: 123456789
... A671: 2025m10 | B671: 99.60316 | C671: 123456789 | D671: 123456789

Sheet import_defl_qm
B1: quarterly_series_interpolated | C1: monthly_series | D1: final_series | F1: the linearly interpolated quarterly series comes from other_series.do
A2: 25569 | B2: 9.9 | D2: =B2 -> 9.9
A3: 25600 | B3: 10 | D3: =B3 -> 10
A4: 25628 | B4: 10.1 | D4: =B4 -> 10.1
A5: 25659 | B5: 10.133333 | D5: =B5 -> 10.133333
A6: 25689 | B6: 10.166667 | D6: =B6 -> 10.166667
A7: 25720 | B7: 10.2 | D7: =B7 -> 10.2
A8: 25750 | B8: 10.233333 | D8: =B8 -> 10.233333
A9: 25781 | B9: 10.266667 | D9: =B9 -> 10.266667
A10: 25812 | B10: 10.3 | D10: =B10 -> 10.3
A11: 25842 | B11: 10.333333 | D11: =B11 -> 10.333333
A12: 25873 | B12: 10.366667 | D12: =B12 -> 10.366667
A13: 25903 | B13: 10.4 | D13: =B13 -> 10.4
... A307: 34851 | B307: 70.4 | D307: =B307 -> 70.4
A308: 34881 | B308: 70.766667 | D308: =B308 -> 70.766667 | H308: CORREL | I308: =CORREL(B326:B664,C326:C664) -> 0.99830556
A309: 34912 | B309: 71.133333 | D309: =B309 -> 71.133333
A310: 34943 | B310: 71.5 | D310: =B310 -> 71.5
A311: 34973 | B311: 71.5 | D311: =B311 -> 71.5
A312: 35004 | B312: 71.5 | D312: =B312 -> 71.5
A313: 35034 | B313: 71.5 | D313: =B313 -> 71.5
A314: 35065 | B314: 71.666667 | D314: =B314 -> 71.666667
A315: 35096 | B315: 71.833333 | D315: =B315 -> 71.833333
A316: 35125 | B316: 72 | D316: =B316 -> 72
A317: 35156 | B317: 72 | D317: =B317 -> 72
A318: 35186 | B318: 72 | D318: =B318 -> 72
A319: 35217 | B319: 72 | D319: =B319 -> 72
A320: 35247 | B320: 71.5 | D320: =B320 -> 71.5
... A325: 35400 | B325: 69.5 | D325: =B325 -> 69.5
A326: 35431 | B326: 68.733333 | C326: =Imp_def_fameGM!B330 -> 65.150055 | D326: =C326 -> 65.150055
A327: 35462 | B327: 67.966667 | C327: =Imp_def_fameGM!B331 -> 64.890167 | D327: =C327 -> 64.890167
A328: 35490 | B328: 67.2 | C328: =Imp_def_fameGM!B332 -> 64.567133 | D328: =C328 -> 64.567133
A329: 35521 | B329: 66.733333 | C329: =Imp_def_fameGM!B333 -> 64.478045 | D329: =C329 -> 64.478045
A330: 35551 | B330: 66.266667 | C330: =Imp_def_fameGM!B334 -> 63.999103 | D330: =C330 -> 63.999103
A331: 35582 | B331: 65.8 | C331: =Imp_def_fameGM!B335 -> 63.18303 | D331: =C331 -> 63.18303
A332: 35612 | B332: 65.666667 | C332: =Imp_def_fameGM!B336 -> 63.634943 | D332: =C332 -> 63.634943
A333: 35643 | B333: 65.533333 | C333: =Imp_def_fameGM!B337 -> 63.10623 | D333: =C333 -> 63.10623
A334: 35674 | B334: 65.4 | C334: =Imp_def_fameGM!B338 -> 63.34046 | D334: =C334 -> 63.34046
A335: 35704 | B335: 65.366667 | C335: =Imp_def_fameGM!B339 -> 63.617535 | D335: =C335 -> 63.617535
A336: 35735 | B336: 65.333333 | C336: =Imp_def_fameGM!B340 -> 62.925864 | D336: =C336 -> 62.925864
A337: 35765 | B337: 65.3 | C337: =Imp_def_fameGM!B341 -> 62.967797 | D337: =C337 -> 62.967797
...

Sheet Sheet1
A1: 1950
A2: 2025
A3: m
A4: famedate | B4: overlay(ikbi.m/ikbl.m*100,convgen(ikbi.q/ikbl.q*100,monthly,averaged,linear,yes))
A5: =[1]!FAMEData(import_defl_FAME!$A$4, import_defl_FAME!$A$1, import_defl_FAME!$A$2, 0,import_defl_FAME!$A$3,"Down","Heading","Normal") -> #N/A | B5: =[1]!FAMEData(B4, import_defl_FAME!$A$1, import_defl_FAME!$A$2, 0,import_defl_FAME!$A$3,"Down","Heading","Normal") -> #N/A

Sheet yoy_growth_import_defl_FAME
B1: UK | C1: US | D1: EA
A2: 1970m1 | B2: 123456789 | C2: 123456789 | D2: 123456789
A3: 1970m2 | B3: 123456789 | C3: 123456789 | D3: 123456789
A4: 1970m3 | B4: 123456789 | C4: 123456789 | D4: 123456789
A5: 1970m4 | B5: 123456789 | C5: 123456789 | D5: 123456789
A6: 1970m5 | B6: 123456789 | C6: 123456789 | D6: 123456789
A7: 1970m6 | B7: 123456789 | C7: 123456789 | D7: 123456789
A8: 1970m7 | B8: 123456789 | C8: 123456789 | D8: 123456789
A9: 1970m8 | B9: 123456789 | C9: 123456789 | D9: 123456789
A10: 1970m9 | B10: 123456789 | C10: 123456789 | D10: 123456789
A11: 1970m10 | B11: 123456789 | C11: 123456789 | D11: 123456789
A12: 1970m11 | B12: 123456789 | C12: 123456789 | D12: 123456789
A13: 1970m12 | B13: 123456789 | C13: 123456789 | D13: 123456789
A14: 1971m1 | B14: =(import_defl_FAME!B14/import_defl_FAME!B2-1)*100 -> 4.6254237 | C14: 123456789 | D14: 123456789
A15: 1971m2 | B15: =(import_defl_FAME!B15/import_defl_FAME!B3-1)*100 -> 3.9026299 | C15: 123456789 | D15: 123456789
A16: 1971m3 | B16: =(import_defl_FAME!B16/import_defl_FAME!B4-1)*100 -> 4.3720623 | C16: 123456789 | D16: 123456789
A17: 1971m4 | B17: =(import_defl_FAME!B17/import_defl_FAME!B5-1)*100 -> 5.0481738 | C17: 123456789 | D17: 123456789
A18: 1971m5 | B18: =(import_defl_FAME!B18/import_defl_FAME!B6-1)*100 -> 5.5957605 | C18: 123456789 | D18: 123456789
A19: 1971m6 | B19: =(import_defl_FAME!B19/import_defl_FAME!B7-1)*100 -> 5.3866288 | C19: 123456789 | D19: 123456789
A20: 1971m7 | B20: =(import_defl_FAME!B20/import_defl_FAME!B8-1)*100 -> 5.0509502 | C20: 123456789 | D20: 123456789
A21: 1971m8 | B21: =(import_defl_FAME!B21/import_defl_FAME!B9-1)*100 -> 4.6739215 | C21: 123456789 | D21: 123456789
A22: 1971m9 | B22: =(import_defl_FAME!B22/import_defl_FAME!B10-1)*100 -> 4.0949646 | C22: 123456789 | D22: 123456789
A23: 1971m10 | B23: =(import_defl_FAME!B23/import_defl_FAME!B11-1)*100 -> 3.4878843 | C23: 123456789 | D23: 123456789
A24: 1971m11 | B24: =(import_defl_FAME!B24/import_defl_FAME!B12-1)*100 -> 2.9306073 | C24: 123456789 | D24: 123456789
A25: 1971m12 | B25: =(import_defl_FAME!B25/import_defl_FAME!B13-1)*100 -> 2.6485282 | C25: 123456789 | D25: 123456789
